Workbook

Sheet BACKEND1
A1: KICTHEN COMMON ITEM DATA COLLECTION SHEET 2025
B2: WHOLE | C2: REMAINDER | D2: R.U.O.M Per W.U.O.M | F2: Weight
A3: Item | B3: Whole Unit of Measurement (W.U.O.M) | C3: Remainder Unit of Measurement (R.U.O.M) | D3: U.O.M | E3: Qty or No. | F3: Empty Tin or Container Or Bottle Weight (Kg)
A4: Condiments
A5: Bread Loaf | B5: Loaf | C5: kg | D5: Kg Per Loaf | E5: 1
A6: Burger Buns | B6: Pcs | C6: Pcs | D6: Pc Per Pkts | E6: 1
A7: Slider Buns | B7: Pcs | C7: Pcs | D7: Pc Per Pkts | E7: 1
A8: Soup Buns | B8: Pcs | C8: Pcs | D8: Pc Per Pkts | E8: 1
A9: Baguette Bread | B9: Pcs | C9: Pcs | D9: Pc Per Pkts | E9: 1
A10: Foccacia Bread | B10: Pcs | C10: Pcs | D10: Pc Per Pkts | E10: 1
A11: White vinegar | B11: Bottles | C11: Liters | D11: Ltrs per Btl | E11: 0.7 | F11: 0.006
A12: Heinz ketchup bottles | B12: Bottles | C12: Bottles | D12: Btls per Btls | E12: 0.305 | F12: 0.195
A13: Apple cider vinegar | B13: Pcs | C13: kg | D13: Ltrs per Btl | E13: 0.473 | F13: 0.037
A14: Balsamic Vinegar | B14: Bottles | C14: Litre | D14: Litre per Bottle | E14: 0.5 | F14: 0.4
A15: Tomato paste | B15: Tins | C15: Kg | D15: Kg Per Tin | E15: 0.4 | F15: 0.063
A16: Tabasco | B16: Pcs | C16: Litre | D16: Kgs per Pc | E16: 0.06 | F16: 0.086
A17: Ketchup sachets | B17: Packet | C17: Pcs | D17: Pcs per Pkt | E17: 100 | F17: 0
A18: Mustard | B18: Bottles | C18: Kg | D18: Kgs per Btl | E18: 0.397 | F18: 0.032
A19: Pancake syrup 710ml | B19: Bottles | C19: Liters | D19: Ltrs per Btl | E19: 0.71 | F19: 0.293
A20: Vanilla esscence | B20: Bottles | C20: Liters | D20: Ltrs per Btl | E20: 1 | F20: 0.056
A21: Srawberry Syrup | B21: Btls | C21: Ltr | D21: Ltr per Btl | E21: 0.623 | F21: 0.057
A22: Caramel syrup | B22: Btls | C22: Ltr | D22: Ltr per Btl | E22: 0.623 | F22: 0.057
... A25: Ketchup 5L | B25: Jerrycan | C25: kg | D25: Ltrs per Btl | E25: 5 | F25: 0.3
A26: Dry Foods
A27: Baking flour | B27: Pkts | C27: Kg | D27: Kg Per Pkts | E27: 2 | F27: 0.05
A28: Baking Powder | B28: Pkts | C28: Kg | D28: Kg Per Pkts | E28: 0.1 | F28: 0.01
A29: Basmati rice | B29: Kg | C29: Kg | D29: Kg Per Kg | E29: 1 | F29: 0.1
A30: Corn flour | B30: Pkts | C30: Kg | D30: Kg Per Pkts | E30: 0.4 | F30: 0.05
A31: Oils, Fats & Creams
A32: Cooking oil 20L | B32: Jerrycan | C32: Liters | D32: Liters Per Jerrycan | E32: 18.4 | F32: 0.81
A33: Croma Butter | B33: Kg | C33: Kg | D33: kg per kg | E33: 1
A34: Prestige | B34: Kg | C34: Kg | D34: Kg Per Kg | E34: 1
A35: Cooking cream | B35: Packs | C35: Liters | D35: Ltrs per Pc | E35: 1 | F35: 0.062
A36: Sunseed Oil 5L | B36: Pcs | C36: Liters | D36: Liters Per Pc | E36: 5 | F36: 0.18
A37: Whipping cream | B37: Packs | C37: Kg | D37: Ltrs per Pc | E37: 1 | F37: 0.062
A38: Olive Oil | B38: Can | C38: Liters | D38: Liters Per Can | E38: 4 | F38: 0.08
A39: Coconut Oil | B39: Jerrycan | C39: Kg | D39: Kg per Jerry | F39: 0.06
A40: Seseame Oil | B40: Bottle | C40: Kg | D40: Kg per Bottle | E40: 0.5 | F40: 0.18
A41: Sauces
A42: Light soy sauce | B42: Bottle | C42: Liters | D42: Ltrs per Btl | E42: 0.5 | F42: 0.412
...

Sheet Printables
A1: PATIO BELLA — KITCHEN COMMON ITEMS COUNTING STOCK CARD
A2: DATE: | C2: SHIFT / SESSION: | E2: COUNTED BY:
A3: ITEM | B3: WHOLE | D3: REMAINDER | F3: UNITS OPENED
A4: ITEM | B4: U.O.M | C4: QTY | D4: U.O.M | E4: QTY | F4: Bottles / Tins / Packets
A5: CONDIMENTS & BREAD
A6: Bread Loaf | B6: Loaf | D6: Loaf
A7: Burger Buns | B7: Pcs | D7: Pcs
A8: Slinder Buns / Mini Burger Buns | B8: Pcs | D8: Pcs
A9: Soup Buns | B9: Pcs | D9: Pcs
A10: Baguette Bread | B10: Pcs | D10: Pcs
A11: Breadcrumbs | B11: Packets | D11: Kg
A12: Chapati Flour | B12: Kg | D12: Kg
A13: DRY FOODS & GRAINS
A14: Baking Flour / Azam | B14: Packets | D14: Kg
A15: Baking Powder | B15: Packets | D15: Kg
A16: Basmati Rice | B16: Sack | D16: Kg
A17: Corn Flour (Starch) | B17: Packets | D17: Kg
A18: Eggs | B18: Tray | D18: Pcs
A19: Penne Pasta | B19: Packets | D19: Kg
A20: Spaghettini | B20: Packets | D20: Kg
A21: Yeast 500g | B21: Packets | D21: Kg
A22: Salt | B22: Packets | D22: Kg
A23: Aji-no-Moto | B23: Packets | D23: Kg
A24: Raisins | B24: Packets | D24: Kg
A25: Sesame Seeds | B25: Packets | D25: Kg
... A27: Black Beans | B27: Kg | D27: Kg
A28: OILS, FATS & CREAMS
A29: Cooking Oil 20L | B29: Jerrycan | D29: Litres
A30: Sunseed Oil 5L | B30: Pcs | D30: Litres
A31: Olive Oil | B31: Can | D31: Litres
A32: Sesame Oil | B32: Tin | D32: Litres
A33: Coconut Oil | B33: Tin | D33: Litres
A34: Croma Butter | B34: Kg | D34: Kg
A35: Unsalted Butter | B35: Kg | D35: Kg
A36: Cooking Cream | B36: Packs | D36: Kg
A37: Whipping Cream | B37: Packs | D37: Kg
A38: Lato Ghee | B38: Tin | D38: Kg
A39: SAUCES & CONDIMENTS
A40: Light Soy Sauce | B40: Bottle | D40: Litres
A41: Dark Soy Sauce | B41: Bottle | D41: Litres
...

Sheet BACKEND2
B2: WHOLE | C2: REMAINDER | D2: R.U.O.M Per W.U.O.M | F2: Weight
A3: Item | B3: Whole Unit of Measurement (W.U.O.M) | C3: Remainder Unit of Measurement (R.U.O.M) | D3: U.O.M | E3: Qty or No. | F3: Portion Weight (Kg)
A4: Carribean jerk | B4: Portions | C4: Pcs | D4: Pcs per ptn | E4: 3 | F4: 450g
A5: Chicken breast | B5: Ptns | C5: Pcs | D5: Pcs per ptn | E5: 2 | F5: 250g
A6: Chicken wings | B6: Ptns | C6: Pcs | D6: Pcs per ptn | E6: 5 | F6: 510g
A7: Chicken burger | B7: Ptns | C7: Ptns | D7: Ptn per ptn | E7: 1 | F7: 130g
A8: Min Chicken burger | B8: Ptns | C8: Pcs | D8: Pcs per ptn | E8: 1 | F8: 75g
A9: Chicken lollipos | B9: Ptns | C9: Pcs | D9: Pcs per ptn | E9: 8 | F9: 420g
A10: Chicken pizza | B10: Ptns | C10: Ptns | D10: Ptn per ptn | E10: 1 | F10: 130g
A11: Chicken Tenders | B11: Ptns | C11: Ptns | D11: Ptn per ptn | E11: 1 | F11: 170g
A12: Chicken skewers | B12: Ptns | C12: Pcs | D12: Pcs per ptn | E12: 9 | F12: 300g
A13: Chicken stroganoff | B13: Ptns | C13: Ptns | D13: Ptn per ptn | E13: 1 | F13: 270g
A14: Chicken spring rolls | B14: Ptns | C14: Pcs | D14: Pcs per ptn | E14: 4 | F14: 200g
A15: Chicken Samosas | B15: Ptns | C15: Pcs | D15: Pcs per ptn | E15: 4 | F15: 200g
... A27: Beef pizza | B27: Ptns | C27: Ptns | D27: Ptn per ptn | E27: 1 | F27: 130g
A28: Beef sausages | B28: Ptns | C28: Pcs | D28: Pcs per ptn | E28: 2
A29: Beef burger patty | B29: Ptns | C29: Ptns | D29: Ptns per ptn | E29: 1 | F29: 150g
A30: Bolognese | B30: Ptns | C30: Ptns | D30: Ptns per ptn | E30: 1 | F30: 150g
A31: Beef samosas | B31: Ptns | C31: Pcs | D31: Pcs per ptn | E31: 4 | F31: 200g
A32: Beef mini burger | B32: Ptns | C32: Ptns | D32: Ptns per ptn | E32: 1 | F32: 75g
A33: Whole fish | B33: Ptns | C33: Ptns | D33: Ptn per ptn | E33: 1 | F33: 1100g
A34: Salmon | B34: Ptns | C34: Ptns | D34: Ptn per ptn | E34: 1 | F34: 27g
A35: Tilapia fillet | B35: Ptns | C35: Pcs | D35: Pcs per ptn | E35: 2 | F35: 300g
A36: Fish fingers | B36: Ptns | C36: Pcs | D36: Pcs per ptn | E36: 4 | F36: 180g
A37: Veg Springs rolls | B37: Ptns | C37: Pcs | D37: Pcs per ptn | E37: 4 | F37: 180g
A38: Veg Samosas | B38: Ptns | C38: Pcs | D38: Pcs per ptn | E38: 4 | F38: 180g
A39: Beef Stew | B39: Ptns | C39: Pcs | D39: Pcs per ptn | E39: 1 | F39: 270g
A40: Beef Minced Meat | B40: Ptns | C40: Pcs | D40: Pcs per ptn | E40: 1 | F40: 150g
A41: Chicken Minced Meat | B41: Ptns | C41: Pcs | D41: Pcs per ptn | E41: 1 | F41: 150g

Sheet Prices
A1: Item | B1: WHOLE W.U.O.M | C1: PURCHASING PRICE (W.U.O.M) | D1: REMAINDER R.U.O.M | E1: R.U.O.M Per W.U.O.M U.O.M | F1: Qty or No. | G1: R.U.O.M Cost Equivalet
A2: Baking Flour / Azam | B2: Packet | C2: 6666 | D2: Kilogram | E2: Kilogram Per Packet | F2: 2 | G2: =C2/F2 -> 3333
A3: Corn flour | B3: Packet | C3: 4000 | D3: Kilogram | E3: Kg Per Packet | F3: 0.4 | G3: =C3/F3 -> 10000
A4: Baking powder | B4: Packet | C4: 1500 | D4: Kilogram | E4: Kg Per Packet | F4: 0.1 | G4: =C4/F4 -> 15000
A5: Oyester Sauce | B5: Bottles | C5: 20000 | D5: Litres | E5: Liters Per Bottle | F5: 0.51 | G5: =C5/F5 -> 39215.686
A6: Worcestershires sauce | B6: Bottles | C6: 15000 | D6: Litres | E6: Litres Per Bottle | F6: 0.295 | G6: =C6/F6 -> 50847.458
A7: Sweet Corn | B7: Tins | C7: 5000 | D7: kg | E7: Kg Per Tin | F7: 0.4 | G7: =C7/F7 -> 12500
A8: Us Mustard | B8: Bottle | C8: 16000 | D8: Kg | E8: Kg Per Tin | F8: 0.4 | G8: =C8/F8 -> 40000
A9: White vinegar | B9: Bottle | C9: 1500 | D9: Litres | E9: Litres Per Bottle | F9: 0.7 | G9: =C9/F9 -> 2142.8571
A10: Apple cider vinegar | B10: Bottles | C10: 13000 | D10: Litres | E10: Litres Per Bottle | F10: 0.473 | G10: =C10/F10 -> 27484.144
A11: Balsamic Vinegar | B11: Bottles | C11: 13000 | D11: Litres | E11: Litres Per Bottle | F11: 0.5 | G11: =C11/F11 -> 26000
A12: Aromat | B12: Tins | C12: 9000 | D12: Kg | E12: Kg Per Tin | F12: 0.2 | G12: =C12/F12 -> 45000
A13: Baked beans | B13: Tins | C13: 7000 | D13: Kg | E13: Kg Per Tin | F13: 0.415 | G13: =C13/F13 -> 16867.47
... A46: Milk fresh | B46: Litres | C46: 2400 | D46: Liters | E46: Litres Per Packet | F46: 1 | G46: =C46/F46 -> 2400
A47: Cumin powder | B47: Pkts | C47: 20000 | D47: Kg | E47: Kg Per Packet | F47: 1 | G47: 20000
A48: Cumin seeds | B48: pkts | C48: 23000 | D48: Kg | E48: Kg Per Packet | F48: 1 | G48: 23000
A49: Chicken tika masala | B49: pkts | C49: 6500 | D49: Kg | E49: Kg Per Packet | F49: 1 | G49: =6500/0.1 -> 65000
A50: Thyme rubbed | B50: pkts | C50: 20000 | D50: Kg | E50: Kg Per Packet | F50: 1 | G50: =C50/F50 -> 20000
A51: Chicken Tikka | B51: pkts | C51: 7400 | D51: kg | E51: Kg Per Packet | F51: 1 | G51: =7400/0.1 -> 74000
A52: Pure tumeric powder | B52: pkts | C52: 35000 | D52: Kg | E52: Kg Per Packet | F52: 1 | G52: =F52*C52 -> 35000
A53: Cinnamon sticks | B53: pkts | C53: 12000 | D53: Kg | E53: Kg Per Packet | F53: 1 | G53: =F53*C53 -> 12000
A54: Oregano powder | B54: pkts | C54: 25000 | D54: Kg | E54: Kg Per Packet | F54: 1 | G54: =F54*C54 -> 25000
A55: Black pepper Powder | B55: pkts | C55: 40000 | D55: Kg | E55: Kg Per Packet | F55: 1 | G55: =F55*C55 -> 40000
A56: Black pepper Seeds | B56: pkts | C56: 40000 | D56: kg | E56: Kg Per Packet | F56: 1 | G56: =F56*C56 -> 40000
A57: Black pepper tin powder | B57: Tins | C57: 13000 | D57: kg | E57: King Per Tin | F57: 1 | G57: =13000/0.1 -> 130000
A58: Sesame seeds | B58: pkts | C58: 23000 | D58: Kg | E58: Kg Per Packet | F58: 1 | G58: =F58*C58 -> 23000
A59: Onion powder | B59: pkts | C59: 22000 | D59: Kg | E59: Kg Per Packet | F59: 1 | G59: =F59*C59 -> 22000
A60: Cloves | B60: pkts | C60: 30000 | D60: Kg | E60: Kg Per Packet | F60: 1 | G60: =F60*C60 -> 30000
A61: Garam masala powder | B61: pkts | C61: 35000 | D61: Kg | E61: Kg Per Packet | F61: 1 | G61: =F61*C61 -> 35000
A62: Brown sugar | B62: Kg | C62: 13000 | D62: Kg | E62: Kg Per Kg | F62: 1 | G62: =F62*C62 -> 13000
A63: Chilli Powder | B63: pkts | C63: 20000 | D63: Kg | E63: Kg Per Packet | F63: 1 | G63: =F63*C63 -> 20000
A64: Cinnamon powder | B64: pkts | C64: 20000 | D64: Kg | E64: Kg Per Packet | F64: 1 | G64: =F64*C64 -> 20000
A65: White pepper powder | B65: pkts | C65: 50000 | D65: Kg | E65: Kg Per Packet | F65: 1 | G65: =F65*C65 -> 50000
A66: Garlic powder | B66: pkts | C66: 20000 | D66: Kg | E66: Kg Per Packet | F66: 1 | G66: =F66*C66 -> 20000
A67: Pillao masala | B67: pkts | C67: 20000 | D67: Kg | E67: Kg Per Packet | F67: 1 | G67: =F67*C67 -> 20000
A68: Nutmeg powder | B68: pkts | C68: 40000 | D68: Kg | E68: Kg Per Packet | F68: 1 | G68: =F68*C68 -> 40000
A69: Corriander powder | B69: pkts | C69: 12000 | D69: Kg | E69: Kg Per Packet | F69: 1 | G69: =12000/0.5 -> 24000
A70: Take away ketchup | B70: pcs | C70: 200 | D70: Pcs | E70: Pcs Per Pcs | F70: 1 | G70: =C70/F70 -> 200
A71: Red onions | B71: kg | C71: 3400 | D71: kg | E71: Kg Per Kg | F71: 1 | G71: =C71/F71 -> 3400
A72: Tomatoes | B72: kg | C72: 2800 | D72: Kg | E72: Kg Per Kg | F72: 1 | G72: =C72/F72 -> 2800
...

Sheet Report Format
A1: Kitchen Performance | G1: PORK RIBS.Normal | H1: 0.49 | I1: BBQ CHICKEN PIZZA.Normal | J1: 0.4
A2: Total Amount Collected | G2: Pan Fried Goat.Normal | H2: 0.45 | I2: Pan Fried Goat.Normal | J2: 0.45
A3: TOP 10 SELLERS | B3: Plates Sold | C3: Amount | D3: COGS% (Pre-Costed) | E3: % of Sales | G3: CARIBEAN JERK.Normal | H3: 0.6 | I3: CARIBEAN JERK.Normal | J3: 0.6
E4: =C4/$B$2 -> #DIV/0! | G4: BBQ CHICKEN PIZZA.Normal | H4: 0.4 | I4: PORK RIBS.Normal | J4: 0.49
E5: =C5/$B$2 -> #DIV/0! | G5: Whole Tilapia tracona.Normal | H5: 0.62 | I5: Whole Tilapia tracona.Normal | J5: 0.62
E6: =C6/$B$2 -> #DIV/0! | G6: Organic Beef Steak.Normal | H6: 0.48 | I6: Chicken Tenders.Normal | J6: 0.3
E7: =C7/$B$2 -> #DIV/0! | G7: Chicken Tikka Masala..Normal | H7: 0.53 | I7: BBQ Chicken Wings.Normal | J7: 0.31
E8: =C8/$B$2 -> #DIV/0! | G8: Classic chicken Burger.Normal | H8: 0.43 | I8: Chicken Tikka Masala..Normal | J8: 0.53
E9: =C9/$B$2 -> #DIV/0! | G9: Tilapia Fillet.Normal | H9: 0.65 | I9: Meaty Feast Pizza.Normal | J9: 0.42
E10: =C10/$B$2 -> #DIV/0! | G10: Balsamic Chicken wings.Normal | H10: 0.31 | I10: Fish Fingers.Normal | J10: 0.71
E11: =C11/$B$2 -> #DIV/0! | G11: EXTRA OVACADO.Normal | H11: 0.23 | I11: Samosas 2 pairs.chicken | J11: 0.43
E12: =C12/$B$2 -> #DIV/0! | G12: STEAMED IRISH / MASH.MASH | H12: 0.32 | I12: Spring Rolls.veg | J12: 0.28
E13: =C13/$B$2 -> #DIV/0! | G13: EXTRAS.mayonaise | H13: 0.27 | I13: KIDDY SAUSAGES WORLD.Normal | J13: 0.12
B14: Total | C14: =sum(C4:C13) -> 0 | E14: =C14/$B$2 -> #DIV/0! | G14: CHAPARTI (1).1 PC | H14: 0.1 | I14: Clear Chicken & Veg Soup.Normal | J14: 0.32
A15: Percentage of all items % | B15: =C14/B2 -> #DIV/0! | G15: GARLIC NAAN.1 PIECE | H15: 0.11 | I15: EXTRAS.ONION RINGS | J15: 0.09
G16: BUTTER NAAN.Normal | H16: 0.1 | I16: POTATO WEDGES.Normal | J16: 0.32
A17: Total Amount Collected | G17: EXTRA SAUCES.1000 island | H17: 0.15 | I17: PLANTAIN.Normal | J17: 0.3
A18: BOTTOM 10 SELLERS | B18: Plates Sold | C18: Amount | D18: COGS% (Pre-Costed) | E18: % of Sales | G18: EXTRA SAUCES.masala sauce | H18: 0.72 | I18: CHAPARTI (1).1 PC | J18: 0.1
E19: =C19/$B$17 -> #DIV/0! | G19: EXTRA SAUCES.Normal | H19: 0.15 | I19: EXTRA OVACADO.Normal | J19: 0.23
E20: =C20/$B$17 -> #DIV/0! | G20: EXTRAS.KACHUMBARI | H20: 0.2 | I20: COSLOW.Normal | J20: 0.27
E21: =C21/$B$17 -> #DIV/0! | G21: SPINACH.Normal | H21: 0.23
E22: =C22/$B$17 -> #DIV/0! | G22: STEAMED IRISH / MASH.STEAMED IRISH | H22: 0.32
E23: =C23/$B$17 -> #DIV/0! | G23: STEAMED IRISH / MASH.MASH | H23: 0.32
E24: =C24/$B$17 -> #DIV/0! | G24: RICE.Normal | H24: 0.16
E25: =C25/$B$17 -> #DIV/0! | G25: EXTRA SAUCES.masala sauce | H25: 0.2
E26: =C26/$B$17 -> #DIV/0! | G26: GARLIC NAAN.1 PIECE | H26: 0.11
E27: =C27/$B$17 -> #DIV/0! | G27: EXTRAS.TOASTED BREAD SLICE | H27: 0.21
E28: =C28/$B$17 -> #DIV/0! | G28: EXTRAS.mayonaise | H28: 0.1
B29: Total | C29: =SUM(C19:C28) -> 0 | E29: =C29/$B$17 -> #DIV/0! | G29: EXTRA OVACADO.Normal | H29: 0.23
A30: Percentage of all items % | B30: =C29/B17 -> #DIV/0! | G30: EXTRA SAUCES.Normal | H30: 0.15
G31: POTATO WEDGES.Normal | H31: 0.32
G32: EXTRA OVACADO.Normal | H32: 0.23
G33: CHAPARTI (1).1 PC | H33: 0.1
G34: EGGS A PAIR.2 EGGS | H34: 0.1
G35: Toast .Normal | H35: 0.2
A36: Item | B36: U.O.M | C36: Qty Used | D36: Cost | G36: EXTRA SAUCES.masala sauce | H36: 0.2
A37: =CogsReport!E3 -> Cooking oil 20L | B37: =CogsReport!F3 -> Liters | C37: =CogsReport!G3 -> 22.9 | D37: =CogsReport!H3 -> 180461.96 | G37: EXTRAS.KACHUMBARI | H37: 0.2
A38: =CogsReport!E4 -> Seseame Oil | B38: =CogsReport!F4 -> Kg | C38: =CogsReport!G4 -> 0.62 | D38: =CogsReport!H4 -> 122368.42 | G38: EXTRA SAUCES.MAYONNAISE | H38: 0.27
A39: =CogsReport!E5 -> Irish potatoes | B39: =CogsReport!F5 -> Kg | C39: =CogsReport!G5 -> 49.85 | D39: =CogsReport!H5 -> 114655 | G39: EXTRAS.mayonaise | H39: 0.27
A40: =CogsReport!E6 -> Mozzarella cheese | B40: =CogsReport!F6 -> Kg | C40: =CogsReport!G6 -> 4 | D40: =CogsReport!H6 -> 88000 | G40: COSLOW.Normal | H40: 0.27
...

Sheet CogsReport
A1: 14thMAY | E1: Other common Items | H1: =SUM(H3:H1000) -> 1149613 | I1: Transfers | J1: =SUM(J3:J1000) -> 0 | K1: Damages | L1: =sum(L3:L1000) -> 0 | N1: Portioned items | Q1: =SUM(Q3:Q1000) -> 932486 | R1: Transfers | S1: =SUM(S3:S1000) -> 0 | T1: Damages | U1: =sum(U3:U1000) -> 0
E2: Item | F2: U.O.M | G2: Qty Used | H2: Cost | I2: Qty | J2: Cost | K2: Qty | L2: Cost | N2: Item | O2: U.O.M | P2: Qty Used | Q2: Cost | R2: Qty | S2: Cost | T2: Qty | U2: Cost
A3: COGS BREAKDOWN BY ACTUAL USAGE | E3: Cooking oil 20L | F3: Liters | G3: =VLOOKUP(E3, INDIRECT("'" & $A$1 & "'!A:O"), 13, FALSE) -> 22.9 | H3: =vlookup(E3, Prices!$A:$G,7,)*G3 -> 180461.96 | I3: {=VLOOKUP(E3, INDIRECT("'" & $A$1 & "'!A:O"), 14, FALSE)} | J3: =vlookup(E3, Prices!$A:$G,7,)*I3 -> 0 | K3: =VLOOKUP(E3, INDIRECT("'" & $A$1 & "'!A:O"), 15, FALSE) | L3: =vlookup(E3, Prices!$A:$G,7,)*K3 -> 0 | N3: Panfried goat | O3: Ptns | P3: {=VLOOKUP(N3, INDIRECT("'" & $A$1 & "'!A:O"), 13, FALSE)/ vlookup(N3,BACKEND2!$A$1:$F1000,5,)} -> 8 | Q3: =vlookup(N3, Prices!$A:$F,3,)*P3 -> 67968 | R3: {=VLOOKUP(N3, INDIRECT("'" & $A$1 & "'!A:O"), 14, FALSE)} | S3: =vlookup(N3, Prices!$A:$G,7,)*R3 -> 0 | T3: =VLOOKUP(N3, INDIRECT("'" & $A$1 & "'!A:O"), 15, FALSE) | U3: =vlookup(N3, Prices!$A:$G,7,)*T3 -> 0
A4: Portions Items Moved | B4: =Q1 -> 932486 | E4: Seseame Oil | F4: Kg | G4: =VLOOKUP(E4, INDIRECT("'" & $A$1 & "'!A:O"), 13, FALSE) -> 0.62 | H4: =vlookup(E4, Prices!$A:$G,7,)*G4 -> 122368.42 | J4: =vlookup(E4, Prices!$A:$G,7,)*I4 -> 0 | K4: =VLOOKUP(E4, INDIRECT("'" & $A$1 & "'!A:O"), 15, FALSE) | L4: =vlookup(E4, Prices!$A:$G,7,)*K4 -> 0 | N4: Chicken wings | O4: Pcs | P4: {=VLOOKUP(N4, INDIRECT("'" & $A$1 & "'!A:O"), 13, FALSE)/ vlookup(N4,BACKEND2!$A$1:$F1000,5,)} -> 11 | Q4: =vlookup(N4, Prices!$A:$F,3,)*P4 -> 99297 | S4: =vlookup(N4, Prices!$A:$G,7,)*R4 -> 0 | T4: =VLOOKUP(N4, INDIRECT("'" & $A$1 & "'!A:O"), 15, FALSE) | U4: =vlookup(N4, Prices!$A:$G,7,)*T4 -> 0 | V4: pork chops | W4: pork ribs | X4: Tilapia Fillet | Y4: chicken wings | Z4: chicken whole breast | AA4: 160 breast
A5: Other Common Items | B5: =H1 -> 1149613 | E5: Irish potatoes | F5: Kg | G5: =VLOOKUP(E5, INDIRECT("'" & $A$1 & "'!A:O"), 13, FALSE) -> 49.85 | H5: =vlookup(E5, Prices!$A:$G,7,)*G5 -> 114655 | I5: =VLOOKUP(E5, INDIRECT("'" & $A$1 & "'!A:O"), 14, FALSE) | J5: =vlookup(E5, Prices!$A:$G,7,)*I5 -> 0 | K5: =VLOOKUP(E5, INDIRECT("'" & $A$1 & "'!A:O"), 15, FALSE) | L5: =vlookup(E5, Prices!$A:$G,7,)*K5 -> 0 | N5: Chicken skewers | O5: Pcs | P5: {=VLOOKUP(N5, INDIRECT("'" & $A$1 & "'!A:O"), 13, FALSE)/ vlookup(N5,BACKEND2!$A$1:$F1000,5,)} -> 5.5 | Q5: =vlookup(N5, Prices!$A:$F,3,)*P5 -> 38940 | R5: =VLOOKUP(N5, INDIRECT("'" & $A$1 & "'!A:O"), 14, FALSE) | S5: =vlookup(N5, Prices!$A:$G,7,)*R5 -> 0 | T5: =VLOOKUP(N5, INDIRECT("'" & $A$1 & "'!A:O"), 15, FALSE) | U5: =vlookup(N5, Prices!$A:$G,7,)*T5 -> 0 | X5: fish fnger | Y5: chicken lollipop | Z5: chicken creole | AA5: chicken curry | AB5: 1
A6: Transfers | B6: =J1 -> 0 | E6: Mozzarella cheese | F6: Kg | G6: =VLOOKUP(E6, INDIRECT("'" & $A$1 & "'!A:O"), 13, FALSE) -> 4 | H6: =vlookup(E6, Prices!$A:$G,7,)*G6 -> 88000 | I6: =VLOOKUP(E6, INDIRECT("'" & $A$1 & "'!A:O"), 14, FALSE) | J6: =vlookup(E6, Prices!$A:$G,7,)*I6 -> 0 | K6: =VLOOKUP(E6, INDIRECT("'" & $A$1 & "'!A:O"), 15, FALSE) | L6: =vlookup(E6, Prices!$A:$G,7,)*K6 -> 0 | N6: Goat ribs | O6: Ptns | P6: {=VLOOKUP(N6, INDIRECT("'" & $A$1 & "'!A:O"), 13, FALSE)/ vlookup(N6,BACKEND2!$A$1:$F1000,5,)} -> 4 | Q6: =vlookup(N6, Prices!$A:$F,3,)*P6 -> 42480 | R6: =VLOOKUP(N6, INDIRECT("'" & $A$1 & "'!A:O"), 14, FALSE) | S6: =vlookup(N6, Prices!$A:$G,7,)*R6 -> 0 | T6: =VLOOKUP(N6, INDIRECT("'" & $A$1 & "'!A:O"), 15, FALSE) | U6: =vlookup(N6, Prices!$A:$G,7,)*T6 -> 0 | X6: ninj turtles | AA6: ceasar salad | AB6: 1
A7: Damages | B7: =L1 -> 0 | E7: Plantain | F7: Cluster | G7: =VLOOKUP(E7, INDIRECT("'" & $A$1 & "'!A:O"), 13, FALSE) -> 9 | H7: =vlookup(E7, Prices!$A:$G,7,)*G7 -> 77142.857 | I7: =VLOOKUP(E7, INDIRECT("'" & $A$1 & "'!A:O"), 14, FALSE) | J7: =vlookup(E7, Prices!$A:$G,7,)*I7 -> 0 | K7: =VLOOKUP(E7, INDIRECT("'" & $A$1 & "'!A:O"), 15, FALSE) | L7: =vlookup(E7, Prices!$A:$G,7,)*K7 -> 0 | N7: Chicken stroganoff | O7: Ptns | P7: {=VLOOKUP(N7, INDIRECT("'" & $A$1 & "'!A:O"), 13, FALSE)/ vlookup(N7,BACKEND2!$A$1:$F1000,5,)} -> 13.5 | Q7: =vlookup(N7, Prices!$A:$F,3,)*P7 -> 54162 | R7: =VLOOKUP(N7, INDIRECT("'" & $A$1 & "'!A:O"), 14, FALSE) | S7: =vlookup(N7, Prices!$A:$G,7,)*R7 -> 0 | T7: =VLOOKUP(N7, INDIRECT("'" & $A$1 & "'!A:O"), 15, FALSE) | U7: =vlookup(N7, Prices!$A:$G,7,)*T7 -> 0 | AA7: chicken sandwich | AB7: 1
A8: Total (Less Transfers) | B8: =sum(B4:B7) -> 2082099 | E8: Patio Bella take away bags | F8: Pcs | G8: =VLOOKUP(E8, INDIRECT("'" & $A$1 & "'!A:O"), 13, FALSE) -> 60 | H8: =vlookup(E8, Prices!$A:$G,7,)*G8 -> 51000 | I8: =VLOOKUP(E8, INDIRECT("'" & $A$1 & "'!A:O"), 14, FALSE) | J8: =vlookup(E8, Prices!$A:$G,7,)*I8 -> 0 | K8: =VLOOKUP(E8, INDIRECT("'" & $A$1 & "'!A:O"), 15, FALSE) | L8: =vlookup(E8, Prices!$A:$G,7,)*K8 -> 0 | N8: Beef burger patty | O8: Ptns | P8: {=VLOOKUP(N8, INDIRECT("'" & $A$1 & "'!A:O"), 13, FALSE)/ vlookup(N8,BACKEND2!$A$1:$F1000,5,)} -> 4 | Q8: =vlookup(N8, Prices!$A:$F,3,)*P8 -> 19116 | R8: =VLOOKUP(N8, INDIRECT("'" & $A$1 & "'!A:O"), 14, FALSE) | S8: =vlookup(N8, Prices!$A:$G,7,)*R8 -> 0 | T8: =VLOOKUP(N8, INDIRECT("'" & $A$1 & "'!A:O"), 15, FALSE) | U8: =vlookup(N8, Prices!$A:$G,7,)*T8 -> 0 | V8: 1kg = 2plates | AA8: maze fit | AB8: 1
E9: Basmati rice | F9: Kg | G9: =VLOOKUP(E9, INDIRECT("'" & $A$1 & "'!A:O"), 13, FALSE) -> 4.9 | H9: =vlookup(E9, Prices!$A:$G,7,)*G9 -> 49000 | I9: =VLOOKUP(E9, INDIRECT("'" & $A$1 & "'!A:O"), 14, FALSE) | J9: =vlookup(E9, Prices!$A:$G,7,)*I9 -> 0 | K9: =VLOOKUP(E9, INDIRECT("'" & $A$1 & "'!A:O"), 15, FALSE) | L9: =vlookup(E9, Prices!$A:$G,7,)*K9 -> 0 | N9: Pork ribs | O9: Ptns | P9: {=VLOOKUP(N9, INDIRECT("'" & $A$1 & "'!A:O"), 13, FALSE)/ vlookup(N9,BACKEND2!$A$1:$F1000,5,)} -> 4 | Q9: =vlookup(N9, Prices!$A:$F,3,)*P9 -> 33180 | R9: =VLOOKUP(N9, INDIRECT("'" & $A$1 & "'!A:O"), 14, FALSE) | S9: =vlookup(N9, Prices!$A:$G,7,)*R9 -> 0 | T9: =VLOOKUP(N9, INDIRECT("'" & $A$1 & "'!A:O"), 15, FALSE) | U9: =vlookup(N9, Prices!$A:$G,7,)*T9 -> 0 | AA9: chicken tender | AB9: 2portions
A10: Performance Summary: Gifts Included in Sales | E10: Pilau masala | F10: Kg | G10: =VLOOKUP(E10, INDIRECT("'" & $A$1 & "'!A:O"), 13, FALSE) -> 0.462 | H10: =vlookup(E10, Prices!$A:$G,7,)*G10 -> 43890 | I10: =VLOOKUP(E10, INDIRECT("'" & $A$1 & "'!A:O"), 14, FALSE) | J10: =vlookup(E10, Prices!$A:$G,7,)*I10 -> 0 | K10: =VLOOKUP(E10, INDIRECT("'" & $A$1 & "'!A:O"), 15, FALSE) | L10: =vlookup(E10, Prices!$A:$G,7,)*K10 -> 0 | N10: Tilapia fillet | O10: Pcs | P10: {=VLOOKUP(N10, INDIRECT("'" & $A$1 & "'!A:O"), 13, FALSE)/ vlookup(N10,BACKEND2!$A$1:$F1000,5,)} -> 3 | Q10: =vlookup(N10, Prices!$A:$F,3,)*P10 -> 30798 | R10: =VLOOKUP(N10, INDIRECT("'" & $A$1 & "'!A:O"), 14, FALSE) | S10: =vlookup(N10, Prices!$A:$G,7,)*R10 -> 0 | T10: =VLOOKUP(N10, INDIRECT("'" & $A$1 & "'!A:O"), 15, FALSE) | U10: =vlookup(N10, Prices!$A:$G,7,)*T10 -> 0 | V10: wings beef steak | AA10: chicken alfedo pasta | AB10: 1
A11: Sales (Gifts Included) | E11: Aromat | F11: Kg | G11: =VLOOKUP(E11, INDIRECT("'" & $A$1 & "'!A:O"), 13, FALSE) -> 0.864 | H11: =vlookup(E11, Prices!$A:$G,7,)*G11 -> 38880 | I11: =VLOOKUP(E11, INDIRECT("'" & $A$1 & "'!A:O"), 14, FALSE) | J11: =vlookup(E11, Prices!$A:$G,7,)*I11 -> 0 | K11: =VLOOKUP(E11, INDIRECT("'" & $A$1 & "'!A:O"), 15, FALSE) | L11: =vlookup(E11, Prices!$A:$G,7,)*K11 -> 0 | N11: Beef sausages | O11: Ptns | P11: {=VLOOKUP(N11, INDIRECT("'" & $A$1 & "'!A:O"), 13, FALSE)/ vlookup(N11,BACKEND2!$A$1:$F1000,5,)} -> 1.5 | Q11: =vlookup(N11, Prices!$A:$F,3,)*P11 -> 6555 | R11: =VLOOKUP(N11, INDIRECT("'" & $A$1 & "'!A:O"), 14, FALSE) | S11: =vlookup(N11, Prices!$A:$G,7,)*R11 -> 0 | T11: =VLOOKUP(N11, INDIRECT("'" & $A$1 & "'!A:O"), 15, FALSE) | U11: =vlookup(N11, Prices!$A:$G,7,)*T11 -> 0 | AA11: chicken alfedo pasta | AB11: 1
A12: Cost of Goods Sold | B12: =B8 -> 2082099 | E12: Baking flour | F12: Kg | G12: =VLOOKUP(E12, INDIRECT("'" & $A$1 & "'!A:O"), 13, FALSE) -> 10.754 | H12: =vlookup(E12, Prices!$A:$G,7,)*G12 -> 35843.082 | I12: =VLOOKUP(E12, INDIRECT("'" & $A$1 & "'!A:O"), 14, FALSE) | J12: =vlookup(E12, Prices!$A:$G,7,)*I12 -> 0 | K12: =VLOOKUP(E12, INDIRECT("'" & $A$1 & "'!A:O"), 15, FALSE) | L12: =vlookup(E12, Prices!$A:$G,7,)*K12 -> 0 | N12: Beef fillet | O12: Ptns | P12: {=VLOOKUP(N12, INDIRECT("'" & $A$1 & "'!A:O"), 13, FALSE)/ vlookup(N12,BACKEND2!$A$1:$F1000,5,)} -> 1 | Q12: =vlookup(N12, Prices!$A:$F,3,)*P12 -> 9558 | R12: =VLOOKUP(N12, INDIRECT("'" & $A$1 & "'!A:O"), 14, FALSE) | S12: =vlookup(N12, Prices!$A:$G,7,)*R12 -> 0 | T12: =VLOOKUP(N12, INDIRECT("'" & $A$1 & "'!A:O"), 15, FALSE) | U12: =vlookup(N12, Prices!$A:$G,7,)*T12 -> 0 | AA12: chicken burger | AB12: 1
A13: Gifts | E13: Tomatoes | F13: Kg | G13: =VLOOKUP(E13, INDIRECT("'" & $A$1 & "'!A:O"), 13, FALSE) -> 8.469 | H13: =vlookup(E13, Prices!$A:$G,7,)*G13 -> 23713.2 | I13: =VLOOKUP(E13, INDIRECT("'" & $A$1 & "'!A:O"), 14, FALSE) | J13: =vlookup(E13, Prices!$A:$G,7,)*I13 -> 0 | K13: =VLOOKUP(E13, INDIRECT("'" & $A$1 & "'!A:O"), 15, FALSE) | L13: =vlookup(E13, Prices!$A:$G,7,)*K13 -> 0 | N13: Bacon | O13: Pcs | P13: {=VLOOKUP(N13, INDIRECT("'" & $A$1 & "'!A:O"), 13, FALSE)/ vlookup(N13,BACKEND2!$A$1:$F1000,5,)} -> 0 | Q13: =vlookup(N13, Prices!$A:$F,3,)*P13 -> 0 | R13: =VLOOKUP(N13, INDIRECT("'" & $A$1 & "'!A:O"), 14, FALSE) | S13: =vlookup(N13, Prices!$A:$G,7,)*R13 -> 0 | T13: =VLOOKUP(N13, INDIRECT("'" & $A$1 & "'!A:O"), 15, FALSE) | U13: =vlookup(N13, Prices!$A:$G,7,)*T13 -> 0 | V13: Sausages | W13: bacon | X13: beef steak | Y13: minced meat | Z13: pork chops | AA13: tuscan pasta | AB13: 1
A14: Profit | B14: =B11-B12 -> -2082099 | E14: Mayonnaise big tin | F14: Kg | G14: =VLOOKUP(E14, INDIRECT("'" & $A$1 & "'!A:O"), 13, FALSE) -> 0.705 | H14: =vlookup(E14, Prices!$A:$G,7,)*G14 -> 22380.952 | I14: =VLOOKUP(E14, INDIRECT("'" & $A$1 & "'!A:O"), 14, FALSE) | J14: =vlookup(E14, Prices!$A:$G,7,)*I14 -> 0 | K14: =VLOOKUP(E14, INDIRECT("'" & $A$1 & "'!A:O"), 15, FALSE) | L14: =vlookup(E14, Prices!$A:$G,7,)*K14 -> 0 | N14: Sizzling pork | O14: Ptns | P14: {=VLOOKUP(N14, INDIRECT("'" & $A$1 & "'!A:O"), 13, FALSE)/ vlookup(N14,BACKEND2!$A$1:$F1000,5,)} -> 1 | Q14: =vlookup(N14, Prices!$A:$F,3,)*P14 -> 6726 | R14: =VLOOKUP(N14, INDIRECT("'" & $A$1 & "'!A:O"), 14, FALSE) | S14: =vlookup(N14, Prices!$A:$G,7,)*R14 -> 0 | T14: =VLOOKUP(N14, INDIRECT("'" & $A$1 & "'!A:O"), 15, FALSE) | U14: =vlookup(N14, Prices!$A:$G,7,)*T14 -> 0 | V14: meat feast (1pc) | W14: classic english | X14: cheese steak | Y14: beef pizza | AA14: classic hawain pizza | AB14: 1
A15: Cogs% | B15: =B12/B11 -> #DIV/0! | E15: Fish Sauce | F15: Liters | G15: =VLOOKUP(E15, INDIRECT("'" & $A$1 & "'!A:O"), 13, FALSE) -> 0.709 | H15: =vlookup(E15, Prices!$A:$G,7,)*G15 -> 21742.667 | I15: =VLOOKUP(E15, INDIRECT("'" & $A$1 & "'!A:O"), 14, FALSE) | J15: =vlookup(E15, Prices!$A:$G,7,)*I15 -> 0 | K15: =VLOOKUP(E15, INDIRECT("'" & $A$1 & "'!A:O"), 15, FALSE) | L15: =vlookup(E15, Prices!$A:$G,7,)*K15 -> 0 | N15: Carribean jerk | O15: Ptns | P15: {=VLOOKUP(N15, INDIRECT("'" & $A$1 & "'!A:O"), 13, FALSE)/ vlookup(N15,BACKEND2!$A$1:$F1000,5,)} -> 3 | Q15: =vlookup(N15, Prices!$A:$F,3,)*P15 -> 19116 | R15: =VLOOKUP(N15, INDIRECT("'" & $A$1 & "'!A:O"), 14, FALSE) | S15: =vlookup(N15, Prices!$A:$G,7,)*R15 -> 0 | T15: =VLOOKUP(N15, INDIRECT("'" & $A$1 & "'!A:O"), 15, FALSE) | U15: =vlookup(N15, Prices!$A:$G,7,)*T15 -> 0 | W15: penna cabonara | X15: teaxs steak slad | Y15: beef samosa | AA15: chiptole chicken bowl | AB15: 1
A16: Profit Margin | B16: =B14/B11 -> #DIV/0! | E16: Oyster sauce | F16: Liters | G16: =VLOOKUP(E16, INDIRECT("'" & $A$1 & "'!A:O"), 13, FALSE) -> 0.532 | H16: =vlookup(E16, Prices!$A:$G,7,)*G16 -> 20862.745 | I16: =VLOOKUP(E16, INDIRECT("'" & $A$1 & "'!A:O"), 14, FALSE) | J16: =vlookup(E16, Prices!$A:$G,7,)*I16 -> 0 | K16: =VLOOKUP(E16, INDIRECT("'" & $A$1 & "'!A:O"), 15, FALSE) | L16: =vlookup(E16, Prices!$A:$G,7,)*K16 -> 0 | N16: Chicken burger | O16: Ptns | P16: {=VLOOKUP(N16, INDIRECT("'" & $A$1 & "'!A:O"), 13, FALSE)/ vlookup(N16,BACKEND2!$A$1:$F1000,5,)} -> 8 | Q16: =vlookup(N16, Prices!$A:$F,3,)*P16 -> 24544 | S16: =vlookup(N16, Prices!$A:$G,7,)*R16 -> 0 | T16: =VLOOKUP(N16, INDIRECT("'" & $A$1 & "'!A:O"), 15, FALSE) | U16: =vlookup(N16, Prices!$A:$G,7,)*T16 -> 0 | Y16: pasta doronez | AA16: katogo | AB16: 3portions
E17: Parmesan cheese | F17: Kg | G17: =VLOOKUP(E17, INDIRECT("'" & $A$1 & "'!A:O"), 13, FALSE) -> 0.214 | H17: =vlookup(E17, Prices!$A:$G,7,)*G17 -> 16906 | I17: =VLOOKUP(E17, INDIRECT("'" & $A$1 & "'!A:O"), 14, FALSE) | J17: =vlookup(E17, Prices!$A:$G,7,)*I17 -> 0 | K17: =VLOOKUP(E17, INDIRECT("'" & $A$1 & "'!A:O"), 15, FALSE) | L17: =vlookup(E17, Prices!$A:$G,7,)*K17 -> 0 | N17: Chicken breast | O17: Pcs | P17: {=VLOOKUP(N17, INDIRECT("'" & $A$1 & "'!A:O"), 13, FALSE)/ vlookup(N17,BACKEND2!$A$1:$F1000,5,)} -> 0 | Q17: =vlookup(N17, Prices!$A:$F,3,)*P17 -> 0 | R17: =VLOOKUP(N17, INDIRECT("'" & $A$1 & "'!A:O"), 14, FALSE) | S17: =vlookup(N17, Prices!$A:$G,7,)*R17 -> 0 | T17: =VLOOKUP(N17, INDIRECT("'" & $A$1 & "'!A:O"), 15, FALSE) | U17: =vlookup(N17, Prices!$A:$G,7,)*T17 -> 0 | V17: Eggs | AA17: chicken and egg wrap
A18: Performance Summary: Gifts Excluded | E18: Square takeaway containers | F18: Pcs | G18: =VLOOKUP(E18, INDIRECT("'" & $A$1 & "'!A:O"), 13, FALSE) -> 35 | H18: =vlookup(E18, Prices!$A:$G,7,)*G18 -> 12460 | I18: =VLOOKUP(E18, INDIRECT("'" & $A$1 & "'!A:O"), 14, FALSE) | J18: =vlookup(E18, Prices!$A:$G,7,)*I18 -> 0 | K18: =VLOOKUP(E18, INDIRECT("'" & $A$1 & "'!A:O"), 15, FALSE) | L18: =vlookup(E18, Prices!$A:$G,7,)*K18 -> 0 | N18: Beef samosas | O18: Pcs | P18: {=VLOOKUP(N18, INDIRECT("'" & $A$1 & "'!A:O"), 13, FALSE)/ vlookup(N18,BACKEND2!$A$1:$F1000,5,)} -> 1 | Q18: =vlookup(N18, Prices!$A:$F,3,)*P18 -> 5756 | R18: =VLOOKUP(N18, INDIRECT("'" & $A$1 & "'!A:O"), 14, FALSE) | S18: =vlookup(N18, Prices!$A:$G,7,)*R18 -> 0 | T18: =VLOOKUP(N18, INDIRECT("'" & $A$1 & "'!A:O"), 15, FALSE) | U18: =vlookup(N18, Prices!$A:$G,7,)*T18 -> 0 | W18: Jerk chicken | X18: chicken pizzza | Y18: minced meat | Z18: Beef steak | AA18: Ham
A19: Sales (Gifts Removed) | B19: =B11 | E19: Ketchup 5L | F19: kg | G19: =VLOOKUP(E19, INDIRECT("'" & $A$1 & "'!A:O"), 13, FALSE) -> 0.953 | H19: =vlookup(E19, Prices!$A:$G,7,)*G19 -> 11436 | I19: =VLOOKUP(E19, INDIRECT("'" & $A$1 & "'!A:O"), 14, FALSE) | J19: =vlookup(E19, Prices!$A:$G,7,)*I19 -> 0 | K19: =VLOOKUP(E19, INDIRECT("'" & $A$1 & "'!A:O"), 15, FALSE) | L19: =vlookup(E19, Prices!$A:$G,7,)*K19 -> 0 | N19: Beef Stew | O19: Ptns | P19: {=VLOOKUP(N19, INDIRECT("'" & $A$1 & "'!A:O"), 13, FALSE)/ vlookup(N19,BACKEND2!$A$1:$F1000,5,)} -> 6 | Q19: =vlookup(N19, Prices!$A:$F,3,)*P19 -> 51612 | R19: =VLOOKUP(N19, INDIRECT("'" & $A$1 & "'!A:O"), 14, FALSE) | S19: =vlookup(N19, Prices!$A:$G,7,)*R19 -> 0 | T19: =VLOOKUP(N19, INDIRECT("'" & $A$1 & "'!A:O"), 15, FALSE) | U19: =vlookup(N19, Prices!$A:$G,7,)*T19 -> 0 | W19: sofia first3 = 2 | Y19: pasta | Z19: steak salad
A20: Cost of Goods Sold | B20: =B12 -> 2082099 | E20: Onions | F20: Kg | G20: =VLOOKUP(E20, INDIRECT("'" & $A$1 & "'!A:O"), 13, FALSE) -> 3.265 | H20: =vlookup(E20, Prices!$A:$G,7,)*G20 -> 11101 | I20: =VLOOKUP(E20, INDIRECT("'" & $A$1 & "'!A:O"), 14, FALSE) | J20: =vlookup(E20, Prices!$A:$G,7,)*I20 -> 0 | K20: =VLOOKUP(E20, INDIRECT("'" & $A$1 & "'!A:O"), 15, FALSE) | L20: =vlookup(E20, Prices!$A:$G,7,)*K20 -> 0 | N20: Beef pizza | O20: Ptns | P20: {=VLOOKUP(N20, INDIRECT("'" & $A$1 & "'!A:O"), 13, FALSE)/ vlookup(N20,BACKEND2!$A$1:$F1000,5,)} -> 1 | Q20: =vlookup(N20, Prices!$A:$F,3,)*P20 -> 4142 | R20: =VLOOKUP(N20, INDIRECT("'" & $A$1 & "'!A:O"), 14, FALSE) | S20: =vlookup(N20, Prices!$A:$G,7,)*R20 -> 0 | T20: =VLOOKUP(N20, INDIRECT("'" & $A$1 & "'!A:O"), 15, FALSE) | U20: =vlookup(N20, Prices!$A:$G,7,)*T20 -> 0 | W20: 1rder = 2 pc | Y20: beef pizza | Z20: beef pilau half portion
A21: Profit | B21: =B19-B20 -> -2082099 | E21: Fresh milk/Jesa | F21: Liters | G21: =VLOOKUP(E21, INDIRECT("'" & $A$1 & "'!A:O"), 13, FALSE) -> 4.5 | H21: =vlookup(E21, Prices!$A:$G,7,)*G21 -> 10800 | I21: =VLOOKUP(E21, INDIRECT("'" & $A$1 & "'!A:O"), 14, FALSE) | J21: =vlookup(E21, Prices!$A:$G,7,)*I21 -> 0 | K21: =VLOOKUP(E21, INDIRECT("'" & $A$1 & "'!A:O"), 15, FALSE) | L21: =vlookup(E21, Prices!$A:$G,7,)*K21 -> 0 | N21: Chicken lollipos | O21: Pcs | P21: {=VLOOKUP(N21, INDIRECT("'" & $A$1 & "'!A:O"), 13, FALSE)/ vlookup(N21,BACKEND2!$A$1:$F1000,5,)} -> 7 | Q21: =vlookup(N21, Prices!$A:$F,3,)*P21 -> 52038 | R21: =VLOOKUP(N21, INDIRECT("'" & $A$1 & "'!A:O"), 14, FALSE) | S21: =vlookup(N21, Prices!$A:$G,7,)*R21 -> 0 | T21: =VLOOKUP(N21, INDIRECT("'" & $A$1 & "'!A:O"), 15, FALSE) | U21: =vlookup(N21, Prices!$A:$G,7,)*T21 -> 0 | Z21: fillys finest half portion
A22: Cogs% | B22: =B20/B19 -> #DIV/0! | E22: Fresh Mushroom | F22: Kg | G22: =VLOOKUP(E22, INDIRECT("'" & $A$1 & "'!A:O"), 13, FALSE) -> 0.95 | H22: =vlookup(E22, Prices!$A:$G,7,)*G22 -> 9500 | I22: =VLOOKUP(E22, INDIRECT("'" & $A$1 & "'!A:O"), 14, FALSE) | J22: =vlookup(E22, Prices!$A:$G,7,)*I22 -> 0 | K22: =VLOOKUP(E22, INDIRECT("'" & $A$1 & "'!A:O"), 15, FALSE) | L22: =vlookup(E22, Prices!$A:$G,7,)*K22 -> 0 | N22: Bolognese | O22: Ptns | P22: {=VLOOKUP(N22, INDIRECT("'" & $A$1 & "'!A:O"), 13, FALSE)/ vlookup(N22,BACKEND2!$A$1:$F1000,5,)} -> 0 | Q22: =vlookup(N22, Prices!$A:$F,3,)*P22 -> 0 | R22: =VLOOKUP(N22, INDIRECT("'" & $A$1 & "'!A:O"), 14, FALSE) | S22: =vlookup(N22, Prices!$A:$G,7,)*R22 -> 0 | T22: =VLOOKUP(N22, INDIRECT("'" & $A$1 & "'!A:O"), 15, FALSE) | U22: =vlookup(N22, Prices!$A:$G,7,)*T22 -> 0 | W22: Sausages | X22: plantain 1cluster =
A23: Profit Margin | B23: =B21/B19 -> #DIV/0! | E23: Garlic | F23: Kg | G23: =VLOOKUP(E23, INDIRECT("'" & $A$1 & "'!A:O"), 13, FALSE) -> 0.694 | H23: =vlookup(E23, Prices!$A:$G,7,)*G23 -> 9369 | I23: =VLOOKUP(E23, INDIRECT("'" & $A$1 & "'!A:O"), 14, FALSE) | J23: =vlookup(E23, Prices!$A:$G,7,)*I23 -> 0 | K23: =VLOOKUP(E23, INDIRECT("'" & $A$1 & "'!A:O"), 15, FALSE) | L23: =vlookup(E23, Prices!$A:$G,7,)*K23 -> 0 | N23: Chicken Samosas | O23: Pcs | P23: {=VLOOKUP(N23, INDIRECT("'" & $A$1 & "'!A:O"), 13, FALSE)/ vlookup(N23,BACKEND2!$A$1:$F1000,5,)} -> 5 | Q23: =vlookup(N23, Prices!$A:$F,3,)*P23 -> 12980 | R23: =VLOOKUP(N23, INDIRECT("'" & $A$1 & "'!A:O"), 14, FALSE) | S23: =vlookup(N23, Prices!$A:$G,7,)*R23 -> 0 | T23: =VLOOKUP(N23, INDIRECT("'" & $A$1 & "'!A:O"), 15, FALSE) | U23: =vlookup(N23, Prices!$A:$G,7,)*T23 -> 0
E24: Yellow pepper | F24: Kg | G24: =VLOOKUP(E24, INDIRECT("'" & $A$1 & "'!A:O"), 13, FALSE) -> 1.035 | H24: =vlookup(E24, Prices!$A:$G,7,)*G24 -> 9315 | I24: =VLOOKUP(E24, INDIRECT("'" & $A$1 & "'!A:O"), 14, FALSE) | J24: =vlookup(E24, Prices!$A:$G,7,)*I24 -> 0 | K24: =VLOOKUP(E24, INDIRECT("'" & $A$1 & "'!A:O"), 15, FALSE) | L24: =vlookup(E24, Prices!$A:$G,7,)*K24 -> 0 | N24: Chicken spring rolls | O24: Pcs | P24: {=VLOOKUP(N24, INDIRECT("'" & $A$1 & "'!A:O"), 13, FALSE)/ vlookup(N24,BACKEND2!$A$1:$F1000,5,)} -> 5 | Q24: =vlookup(N24, Prices!$A:$F,3,)*P24 -> 23600 | R24: =VLOOKUP(N24, INDIRECT("'" & $A$1 & "'!A:O"), 14, FALSE) | S24: =vlookup(N24, Prices!$A:$G,7,)*R24 -> 0 | T24: =VLOOKUP(N24, INDIRECT("'" & $A$1 & "'!A:O"), 15, FALSE) | U24: =vlookup(N24, Prices!$A:$G,7,)*T24 -> 0
A25: TOP 10 SELLERS | B25: plates/portions | C25: Amount | E25: Ketchup sachets | F25: Pcs | G25: =VLOOKUP(E25, INDIRECT("'" & $A$1 & "'!A:O"), 13, FALSE) -> 45 | H25: =vlookup(E25, Prices!$A:$G,7,)*G25 -> 9000 | I25: =VLOOKUP(E25, INDIRECT("'" & $A$1 & "'!A:O"), 14, FALSE) | J25: =vlookup(E25, Prices!$A:$G,7,)*I25 -> 0 | K25: =VLOOKUP(E25, INDIRECT("'" & $A$1 & "'!A:O"), 15, FALSE) | L25: =vlookup(E25, Prices!$A:$G,7,)*K25 -> 0 | N25: Chicken pizza | O25: Ptns | P25: {=VLOOKUP(N25, INDIRECT("'" & $A$1 & "'!A:O"), 13, FALSE)/ vlookup(N25,BACKEND2!$A$1:$F1000,5,)} -> 11 | Q25: =vlookup(N25, Prices!$A:$F,3,)*P25 -> 33748 | R25: =VLOOKUP(N25, INDIRECT("'" & $A$1 & "'!A:O"), 14, FALSE) | S25: =vlookup(N25, Prices!$A:$G,7,)*R25 -> 0 | T25: =VLOOKUP(N25, INDIRECT("'" & $A$1 & "'!A:O"), 15, FALSE) | U25: =vlookup(N25, Prices!$A:$G,7,)*T25 -> 0
E26: Red pepper | F26: Kg | G26: =VLOOKUP(E26, INDIRECT("'" & $A$1 & "'!A:O"), 13, FALSE) -> 0.891 | H26: =vlookup(E26, Prices!$A:$G,7,)*G26 -> 8019 | I26: =VLOOKUP(E26, INDIRECT("'" & $A$1 & "'!A:O"), 14, FALSE) | J26: =vlookup(E26, Prices!$A:$G,7,)*I26 -> 0 | K26: =VLOOKUP(E26, INDIRECT("'" & $A$1 & "'!A:O"), 15, FALSE) | L26: =vlookup(E26, Prices!$A:$G,7,)*K26 -> 0 | N26: Veg Samosas | O26: Pcs | P26: {=VLOOKUP(N26, INDIRECT("'" & $A$1 & "'!A:O"), 13, FALSE)/ vlookup(N26,BACKEND2!$A$1:$F1000,5,)} -> 1 | Q26: =vlookup(N26, Prices!$A:$F,3,)*P26 -> 2000 | R26: =VLOOKUP(N26, INDIRECT("'" & $A$1 & "'!A:O"), 14, FALSE) | S26: =vlookup(N26, Prices!$A:$G,7,)*R26 -> 0 | T26: =VLOOKUP(N26, INDIRECT("'" & $A$1 & "'!A:O"), 15, FALSE) | U26: =vlookup(N26, Prices!$A:$G,7,)*T26 -> 0 | W26: Irish container
E27: Light soy sauce | F27: Liters | G27: =VLOOKUP(E27, INDIRECT("'" & $A$1 & "'!A:O"), 13, FALSE) -> 0.5 | H27: =vlookup(E27, Prices!$A:$G,7,)*G27 -> 8000 | J27: =vlookup(E27, Prices!$A:$G,7,)*I27 -> 0 | K27: =VLOOKUP(E27, INDIRECT("'" & $A$1 & "'!A:O"), 15, FALSE) | L27: =vlookup(E27, Prices!$A:$G,7,)*K27 -> 0 | N27: Whole fish | O27: Ptns | P27: {=VLOOKUP(N27, INDIRECT("'" & $A$1 & "'!A:O"), 13, FALSE)/ vlookup(N27,BACKEND2!$A$1:$F1000,5,)} -> 7 | Q27: =vlookup(N27, Prices!$A:$F,3,)*P27 -> 112000 | R27: =VLOOKUP(N27, INDIRECT("'" & $A$1 & "'!A:O"), 14, FALSE) | S27: =vlookup(N27, Prices!$A:$G,7,)*R27 -> 0 | T27: =VLOOKUP(N27, INDIRECT("'" & $A$1 & "'!A:O"), 15, FALSE) | U27: =vlookup(N27, Prices!$A:$G,7,)*T27 -> 0 | W27: 0.415
E28: Cherry Tomatoes | F28: Kg | G28: =VLOOKUP(E28, INDIRECT("'" & $A$1 & "'!A:O"), 13, FALSE) -> 0.384 | H28: =vlookup(E28, Prices!$A:$G,7,)*G28 -> 7822.2222 | I28: =VLOOKUP(E28, INDIRECT("'" & $A$1 & "'!A:O"), 14, FALSE) | J28: =vlookup(E28, Prices!$A:$G,7,)*I28 -> 0 | K28: =VLOOKUP(E28, INDIRECT("'" & $A$1 & "'!A:O"), 15, FALSE) | L28: =vlookup(E28, Prices!$A:$G,7,)*K28 -> 0 | N28: Pork chops | O28: Pcs | P28: {=VLOOKUP(N28, INDIRECT("'" & $A$1 & "'!A:O"), 13, FALSE)/ vlookup(N28,BACKEND2!$A$1:$F1000,5,)} -> 2 | Q28: =vlookup(N28, Prices!$A:$F,3,)*P28 -> 20084 | R28: =VLOOKUP(N28, INDIRECT("'" & $A$1 & "'!A:O"), 14, FALSE) | S28: =vlookup(N28, Prices!$A:$G,7,)*R28 -> 0 | T28: =VLOOKUP(N28, INDIRECT("'" & $A$1 & "'!A:O"), 15, FALSE) | U28: =vlookup(N28, Prices!$A:$G,7,)*T28 -> 0
E29: Eggs | F29: Pcs | G29: =VLOOKUP(E29, INDIRECT("'" & $A$1 & "'!A:O"), 13, FALSE) -> 19 | H29: =vlookup(E29, Prices!$A:$G,7,)*G29 -> 7600 | I29: =VLOOKUP(E29, INDIRECT("'" & $A$1 & "'!A:O"), 14, FALSE) | J29: =vlookup(E29, Prices!$A:$G,7,)*I29 -> 0 | K29: =VLOOKUP(E29, INDIRECT("'" & $A$1 & "'!A:O"), 15, FALSE) | L29: =vlookup(E29, Prices!$A:$G,7,)*K29 -> 0 | N29: Goat stew | O29: Ptns | P29: {=VLOOKUP(N29, INDIRECT("'" & $A$1 & "'!A:O"), 13, FALSE)/ vlookup(N29,BACKEND2!$A$1:$F1000,5,)} -> 1 | Q29: =vlookup(N29, Prices!$A:$F,3,)*P29 -> 6372 | R29: =VLOOKUP(N29, INDIRECT("'" & $A$1 & "'!A:O"), 14, FALSE) | S29: =vlookup(N29, Prices!$A:$G,7,)*R29 -> 0 | T29: =VLOOKUP(N29, INDIRECT("'" & $A$1 & "'!A:O"), 15, FALSE) | U29: =vlookup(N29, Prices!$A:$G,7,)*T29 -> 0 | W29: 7kgs = peelings 1.5
E30: Babby Marrow | F30: Pcs | G30: =VLOOKUP(E30, INDIRECT("'" & $A$1 & "'!A:O"), 13, FALSE) -> 2 | H30: =vlookup(E30, Prices!$A:$G,7,)*G30 -> 7000 | I30: =VLOOKUP(E30, INDIRECT("'" & $A$1 & "'!A:O"), 14, FALSE) | J30: =vlookup(E30, Prices!$A:$G,7,)*I30 -> 0 | K30: =VLOOKUP(E30, INDIRECT("'" & $A$1 & "'!A:O"), 15, FALSE) | L30: =vlookup(E30, Prices!$A:$G,7,)*K30 -> 0 | N30: Fish fingers | O30: Pcs | P30: {=VLOOKUP(N30, INDIRECT("'" & $A$1 & "'!A:O"), 13, FALSE)/ vlookup(N30,BACKEND2!$A$1:$F1000,5,)} -> 1 | Q30: =vlookup(N30, Prices!$A:$F,3,)*P30 -> 6160 | R30: =VLOOKUP(N30, INDIRECT("'" & $A$1 & "'!A:O"), 14, FALSE) | S30: =vlookup(N30, Prices!$A:$G,7,)*R30 -> 0 | T30: =VLOOKUP(N30, INDIRECT("'" & $A$1 & "'!A:O"), 15, FALSE) | U30: =vlookup(N30, Prices!$A:$G,7,)*T30 -> 0
E31: Baked Beans | F31: Kg | G31: =VLOOKUP(E31, INDIRECT("'" & $A$1 & "'!A:O"), 13, FALSE) -> 0.394 | H31: =vlookup(E31, Prices!$A:$G,7,)*G31 -> 6645.7831 | I31: =VLOOKUP(E31, INDIRECT("'" & $A$1 & "'!A:O"), 14, FALSE) | J31: =vlookup(E31, Prices!$A:$G,7,)*I31 -> 0 | K31: =VLOOKUP(E31, INDIRECT("'" & $A$1 & "'!A:O"), 15, FALSE) | L31: =vlookup(E31, Prices!$A:$G,7,)*K31 -> 0 | N31: Veg Springs rolls | O31: Pcs | P31: {=VLOOKUP(N31, INDIRECT("'" & $A$1 & "'!A:O"), 13, FALSE)/ vlookup(N31,BACKEND2!$A$1:$F1000,5,)} -> 0 | Q31: =vlookup(N31, Prices!$A:$F,3,)*P31 -> 0 | R31: =VLOOKUP(N31, INDIRECT("'" & $A$1 & "'!A:O"), 14, FALSE) | S31: =vlookup(N31, Prices!$A:$G,7,)*R31 -> 0 | T31: =VLOOKUP(N31, INDIRECT("'" & $A$1 & "'!A:O"), 15, FALSE) | U31: =vlookup(N31, Prices!$A:$G,7,)*T31 -> 0
E32: Burger Buns | F32: Pcs | G32: =VLOOKUP(E32, INDIRECT("'" & $A$1 & "'!A:O"), 13, FALSE) -> 14 | H32: =vlookup(E32, Prices!$A:$G,7,)*G32 -> 6510 | I32: =VLOOKUP(E32, INDIRECT("'" & $A$1 & "'!A:O"), 14, FALSE) | J32: =vlookup(E32, Prices!$A:$G,7,)*I32 -> 0 | K32: =VLOOKUP(E32, INDIRECT("'" & $A$1 & "'!A:O"), 15, FALSE) | L32: =vlookup(E32, Prices!$A:$G,7,)*K32 -> 0 | N32: Beef Minced Meat | O32: Ptns | P32: {=VLOOKUP(N32, INDIRECT("'" & $A$1 & "'!A:O"), 13, FALSE)/ vlookup(N32,BACKEND2!$A$1:$F1000,5,)} -> 6 | Q32: =vlookup(N32, Prices!$A:$F,3,)*P32 -> 13500 | R32: =VLOOKUP(N32, INDIRECT("'" & $A$1 & "'!A:O"), 14, FALSE) | S32: =vlookup(N32, Prices!$A:$G,7,)*R32 -> 0 | T32: =VLOOKUP(N32, INDIRECT("'" & $A$1 & "'!A:O"), 15, FALSE) | U32: =vlookup(N32, Prices!$A:$G,7,)*T32 -> 0
E33: Green pepper | F33: Kg | G33: =VLOOKUP(E33, INDIRECT("'" & $A$1 & "'!A:O"), 13, FALSE) -> 1.631 | H33: =vlookup(E33, Prices!$A:$G,7,)*G33 -> 6197.8 | I33: =VLOOKUP(E33, INDIRECT("'" & $A$1 & "'!A:O"), 14, FALSE) | J33: =vlookup(E33, Prices!$A:$G,7,)*I33 -> 0 | K33: =VLOOKUP(E33, INDIRECT("'" & $A$1 & "'!A:O"), 15, FALSE) | L33: =vlookup(E33, Prices!$A:$G,7,)*K33 -> 0 | N33: Pork pizza | O33: Ptns | P33: {=VLOOKUP(N33, INDIRECT("'" & $A$1 & "'!A:O"), 13, FALSE)/ vlookup(N33,BACKEND2!$A$1:$F1000,5,)} -> 1 | Q33: =vlookup(N33, Prices!$A:$F,3,)*P33 -> 2242 | R33: =VLOOKUP(N33, INDIRECT("'" & $A$1 & "'!A:O"), 14, FALSE) | S33: =vlookup(N33, Prices!$A:$G,7,)*R33 -> 0 | T33: =VLOOKUP(N33, INDIRECT("'" & $A$1 & "'!A:O"), 15, FALSE) | U33: =vlookup(N33, Prices!$A:$G,7,)*T33 -> 0
E34: Cauliflower | F34: Pcs | G34: =VLOOKUP(E34, INDIRECT("'" & $A$1 & "'!A:O"), 13, FALSE) -> 1.5 | H34: =vlookup(E34, Prices!$A:$G,7,)*G34 -> 5700 | I34: =VLOOKUP(E34, INDIRECT("'" & $A$1 & "'!A:O"), 14, FALSE) | J34: =vlookup(E34, Prices!$A:$G,7,)*I34 -> 0 | K34: =VLOOKUP(E34, INDIRECT("'" & $A$1 & "'!A:O"), 15, FALSE) | L34: =vlookup(E34, Prices!$A:$G,7,)*K34 -> 0 | N34: Salmon | O34: Ptns | P34: {=VLOOKUP(N34, INDIRECT("'" & $A$1 & "'!A:O"), 13, FALSE)/ vlookup(N34,BACKEND2!$A$1:$F1000,5,)} -> 3 | Q34: =vlookup(N34, Prices!$A:$F,3,)*P34 -> 133812 | R34: =VLOOKUP(N34, INDIRECT("'" & $A$1 & "'!A:O"), 14, FALSE) | S34: =vlookup(N34, Prices!$A:$G,7,)*R34 -> 0 | T34: =VLOOKUP(N34, INDIRECT("'" & $A$1 & "'!A:O"), 15, FALSE) | U34: =vlookup(N34, Prices!$A:$G,7,)*T34 -> 0
E35: Croma Butter | F35: Kg | G35: =VLOOKUP(E35, INDIRECT("'" & $A$1 & "'!A:O"), 13, FALSE) -> 0.58 | H35: =vlookup(E35, Prices!$A:$G,7,)*G35 -> 5510 | I35: =VLOOKUP(E35, INDIRECT("'" & $A$1 & "'!A:O"), 14, FALSE) | J35: =vlookup(E35, Prices!$A:$G,7,)*I35 -> 0 | K35: =VLOOKUP(E35, INDIRECT("'" & $A$1 & "'!A:O"), 15, FALSE) | L35: =vlookup(E35, Prices!$A:$G,7,)*K35 -> 0 | N35: Min Chicken burger | O35: Pcs | P35: {=VLOOKUP(N35, INDIRECT("'" & $A$1 & "'!A:O"), 13, FALSE)/ vlookup(N35,BACKEND2!$A$1:$F1000,5,)} -> 0 | Q35: =vlookup(N35, Prices!$A:$F,3,)*P35 -> 0 | S35: =vlookup(N35, Prices!$A:$G,7,)*R35 -> 0 | U35: =vlookup(N35, Prices!$A:$G,7,)*T35 -> 0
B36: Total | C36: =SUM(C26:C35) -> 0 | E36: Aluminium foil | F36: Kg | G36: =VLOOKUP(E36, INDIRECT("'" & $A$1 & "'!A:O"), 13, FALSE) -> 0.441 | H36: =vlookup(E36, Prices!$A:$G,7,)*G36 -> 5292 | I36: =VLOOKUP(E36, INDIRECT("'" & $A$1 & "'!A:O"), 14, FALSE) | J36: =vlookup(E36, Prices!$A:$G,7,)*I36 -> 0 | K36: =VLOOKUP(E36, INDIRECT("'" & $A$1 & "'!A:O"), 15, FALSE) | L36: =vlookup(E36, Prices!$A:$G,7,)*K36 -> 0 | N36: Chicken Tenders | O36: Ptns | P36: {=VLOOKUP(N36, INDIRECT("'" & $A$1 & "'!A:O"), 13, FALSE)/ vlookup(N36,BACKEND2!$A$1:$F1000,5,)} -> 0 | Q36: =vlookup(N36, Prices!$A:$F,3,)*P36 -> 0 | S36: =vlookup(N36, Prices!$A:$G,7,)*R36 -> 0 | U36: =vlookup(N36, Prices!$A:$G,7,)*T36 -> 0
A37: Percentage of all items % | B37: =C36/B19 -> #DIV/0! | E37: Cling film | F37: Kg | G37: =VLOOKUP(E37, INDIRECT("'" & $A$1 & "'!A:O"), 13, FALSE) -> 0.277 | H37: =vlookup(E37, Prices!$A:$G,7,)*G37 -> 5061.9289 | I37: =VLOOKUP(E37, INDIRECT("'" & $A$1 & "'!A:O"), 14, FALSE) | J37: =vlookup(E37, Prices!$A:$G,7,)*I37 -> 0 | K37: =VLOOKUP(E37, INDIRECT("'" & $A$1 & "'!A:O"), 15, FALSE) | L37: =vlookup(E37, Prices!$A:$G,7,)*K37 -> 0 | N37: Bacon Warp | O37: Pcs | P37: {=VLOOKUP(N37, INDIRECT("'" & $A$1 & "'!A:O"), 13, FALSE)/ vlookup(N37,BACKEND2!$A$1:$F1000,5,)} -> 0 | Q37: =vlookup(N37, Prices!$A:$F,3,)*P37 -> 0 | S37: =vlookup(N37, Prices!$A:$G,7,)*R37 -> 0 | U37: =vlookup(N37, Prices!$A:$G,7,)*T37 -> 0
E38: Tomato paste | F38: Kg | G38: =VLOOKUP(E38, INDIRECT("'" & $A$1 & "'!A:O"), 13, FALSE) -> 0.4 | H38: =vlookup(E38, Prices!$A:$G,7,)*G38 -> 5000 | I38: =VLOOKUP(E38, INDIRECT("'" & $A$1 & "'!A:O"), 14, FALSE) | J38: =vlookup(E38, Prices!$A:$G,7,)*I38 -> 0 | K38: =VLOOKUP(E38, INDIRECT("'" & $A$1 & "'!A:O"), 15, FALSE) | L38: =vlookup(E38, Prices!$A:$G,7,)*K38 -> 0 | N38: Beef stragnoff | O38: Ptns | P38: {=VLOOKUP(N38, INDIRECT("'" & $A$1 & "'!A:O"), 13, FALSE)/ vlookup(N38,BACKEND2!$A$1:$F1000,5,)} -> 0 | Q38: =vlookup(N38, Prices!$A:$F,3,)*P38 -> 0 | S38: =vlookup(N38, Prices!$A:$G,7,)*R38 -> 0 | U38: =vlookup(N38, Prices!$A:$G,7,)*T38 -> 0
E39: Chips bags | F39: Pcs | G39: =VLOOKUP(E39, INDIRECT("'" & $A$1 & "'!A:O"), 13, FALSE) -> 60 | H39: =vlookup(E39, Prices!$A:$G,7,)*G39 -> 4200 | I39: =VLOOKUP(E39, INDIRECT("'" & $A$1 & "'!A:O"), 14, FALSE) | J39: =vlookup(E39, Prices!$A:$G,7,)*I39 -> 0 | K39: =VLOOKUP(E39, INDIRECT("'" & $A$1 & "'!A:O"), 15, FALSE) | L39: =vlookup(E39, Prices!$A:$G,7,)*K39 -> 0 | N39: Beef mini burger | O39: Ptns | P39: {=VLOOKUP(N39, INDIRECT("'" & $A$1 & "'!A:O"), 13, FALSE)/ vlookup(N39,BACKEND2!$A$1:$F1000,5,)} -> 0 | Q39: =vlookup(N39, Prices!$A:$F,3,)*P39 -> 0 | S39: =vlookup(N39, Prices!$A:$G,7,)*R39 -> 0 | U39: =vlookup(N39, Prices!$A:$G,7,)*T39 -> 0
E40: Bread Loaf | F40: kg | G40: =VLOOKUP(E40, INDIRECT("'" & $A$1 & "'!A:O"), 13, FALSE) -> 1 | H40: =vlookup(E40, Prices!$A:$G,7,)*G40 -> 3876 | I40: =VLOOKUP(E40, INDIRECT("'" & $A$1 & "'!A:O"), 14, FALSE) | J40: =vlookup(E40, Prices!$A:$G,7,)*I40 -> 0 | K40: =VLOOKUP(E40, INDIRECT("'" & $A$1 & "'!A:O"), 15, FALSE) | L40: =vlookup(E40, Prices!$A:$G,7,)*K40 -> 0
...

Sheet Temp1
B2: WHOLE | F2: REMAINDER | L2: ACCOUNTABILITY
A3: Type | B3: U.O.M | C3: Opening | D3: Added | E3: Closing | F3: U.O.M | G3: Added | H3: Opening | I3: Units | J3: Closing | K3: Units | L3: U.O.M | M3: Used | N3: Transfer | O3: Damage
A4: Portioned Items: Meats & Others
A5: Carribean jerk | B5: Ptns | F5: Pcs | L5: Pcs | M5: =IF(AND(H5<>"", J5<>""), H5-J5, IF(H5<>"", H5-I5*VLOOKUP(A5, BACKEND2!$A:$G,6,FALSE), IF(J5<>"", -J5+K5*VLOOKUP(A5, BACKEND2!$A:$G,6,FALSE),0)))+ (C5+D5-E5)*VLOOKUP(A5, BACKEND2!$A:$G,5,FALSE)+G5 -> 0
A6: Chicken breast | B6: Ptns | F6: Pcs | L6: Pcs | M6: =IF(AND(H6<>"", J6<>""), H6-J6, IF(H6<>"", H6-I6*VLOOKUP(A6, BACKEND2!$A:$G,6,FALSE), IF(J6<>"", -J6+K6*VLOOKUP(A6, BACKEND2!$A:$G,6,FALSE),0)))+ (C6+D6-E6)*VLOOKUP(A6, BACKEND2!$A:$G,5,FALSE)+G6 -> 0
A7: Chicken wings | B7: Ptns | F7: Pcs | L7: Pcs | M7: =IF(AND(H7<>"", J7<>""), H7-J7, IF(H7<>"", H7-I7*VLOOKUP(A7, BACKEND2!$A:$G,6,FALSE), IF(J7<>"", -J7+K7*VLOOKUP(A7, BACKEND2!$A:$G,6,FALSE),0)))+ (C7+D7-E7)*VLOOKUP(A7, BACKEND2!$A:$G,5,FALSE)+G7 -> 0
A8: Chicken burger | B8: Ptns | F8: Ptns | L8: Ptns | M8: =IF(AND(H8<>"", J8<>""), H8-J8, IF(H8<>"", H8-I8*VLOOKUP(A8, BACKEND2!$A:$G,6,FALSE), IF(J8<>"", -J8+K8*VLOOKUP(A8, BACKEND2!$A:$G,6,FALSE),0)))+ (C8+D8-E8)*VLOOKUP(A8, BACKEND2!$A:$G,5,FALSE)+G8 -> 0
A9: Min Chicken burger | B9: Ptns | F9: Pcs | L9: Pcs | M9: =IF(AND(H9<>"", J9<>""), H9-J9, IF(H9<>"", H9-I9*VLOOKUP(A9, BACKEND2!$A:$G,6,FALSE), IF(J9<>"", -J9+K9*VLOOKUP(A9, BACKEND2!$A:$G,6,FALSE),0)))+ (C9+D9-E9)*VLOOKUP(A9, BACKEND2!$A:$G,5,FALSE)+G9 -> 0
A10: Chicken lollipos | B10: Ptns | F10: Pcs | L10: Pcs | M10: =IF(AND(H10<>"", J10<>""), H10-J10, IF(H10<>"", H10-I10*VLOOKUP(A10, BACKEND2!$A:$G,6,FALSE), IF(J10<>"", -J10+K10*VLOOKUP(A10, BACKEND2!$A:$G,6,FALSE),0)))+ (C10+D10-E10)*VLOOKUP(A10, BACKEND2!$A:$G,5,FALSE)+G10 -> 0
A11: Chicken pizza | B11: Ptns | F11: Ptns | L11: Ptns | M11: =IF(AND(H11<>"", J11<>""), H11-J11, IF(H11<>"", H11-I11*VLOOKUP(A11, BACKEND2!$A:$G,6,FALSE), IF(J11<>"", -J11+K11*VLOOKUP(A11, BACKEND2!$A:$G,6,FALSE),0)))+ (C11+D11-E11)*VLOOKUP(A11, BACKEND2!$A:$G,5,FALSE)+G11 -> 0
A12: Chicken Tenders | B12: Ptns | F12: Ptns | L12: Ptns | M12: =IF(AND(H12<>"", J12<>""), H12-J12, IF(H12<>"", H12-I12*VLOOKUP(A12, BACKEND2!$A:$G,6,FALSE), IF(J12<>"", -J12+K12*VLOOKUP(A12, BACKEND2!$A:$G,6,FALSE),0)))+ (C12+D12-E12)*VLOOKUP(A12, BACKEND2!$A:$G,5,FALSE)+G12 -> 0
A13: Chicken skewers | B13: Ptns | F13: Pcs | L13: Pcs | M13: =IF(AND(H13<>"", J13<>""), H13-J13, IF(H13<>"", H13-I13*VLOOKUP(A13, BACKEND2!$A:$G,6,FALSE), IF(J13<>"", -J13+K13*VLOOKUP(A13, BACKEND2!$A:$G,6,FALSE),0)))+ (C13+D13-E13)*VLOOKUP(A13, BACKEND2!$A:$G,5,FALSE)+G13 -> 0
A14: Chicken stroganoff | B14: Ptns | F14: Ptns | L14: Ptns | M14: =IF(AND(H14<>"", J14<>""), H14-J14, IF(H14<>"", H14-I14*VLOOKUP(A14, BACKEND2!$A:$G,6,FALSE), IF(J14<>"", -J14+K14*VLOOKUP(A14, BACKEND2!$A:$G,6,FALSE),0)))+ (C14+D14-E14)*VLOOKUP(A14, BACKEND2!$A:$G,5,FALSE)+G14 -> 0
A15: Chicken spring rolls | B15: Ptns | F15: Pcs | L15: Pcs | M15: =IF(AND(H15<>"", J15<>""), H15-J15, IF(H15<>"", H15-I15*VLOOKUP(A15, BACKEND2!$A:$G,6,FALSE), IF(J15<>"", -J15+K15*VLOOKUP(A15, BACKEND2!$A:$G,6,FALSE),0)))+ (C15+D15-E15)*VLOOKUP(A15, BACKEND2!$A:$G,5,FALSE)+G15 -> 0
A16: Chicken Samosas | B16: Ptns | F16: Pcs | L16: Pcs | M16: =IF(AND(H16<>"", J16<>""), H16-J16, IF(H16<>"", H16-I16*VLOOKUP(A16, BACKEND2!$A:$G,6,FALSE), IF(J16<>"", -J16+K16*VLOOKUP(A16, BACKEND2!$A:$G,6,FALSE),0)))+ (C16+D16-E16)*VLOOKUP(A16, BACKEND2!$A:$G,5,FALSE)+G16 -> 0
... A41: Beef Minced Meat | B41: Ptns | F41: Pcs | L41: Pcs | M41: =IF(AND(H41<>"", J41<>""), H41-J41, IF(H41<>"", H41-I41*VLOOKUP(A41, BACKEND2!$A:$G,6,FALSE), IF(J41<>"", -J41+K41*VLOOKUP(A41, BACKEND2!$A:$G,6,FALSE),0)))+ (C41+D41-E41)*VLOOKUP(A41, BACKEND2!$A:$G,5,FALSE)+G41 -> 0
A42: Other Kitchen & Food Supplies
A43: Condiments
A44: Bread Loaf | B44: Loaf | F44: kg | L44: kg | M44: =IF(AND(H44<>"", J44<>""), H44-J44, IF(H44<>"", H44-I44*VLOOKUP(A44, BACKEND1!$A:$G,6,FALSE), IF(J44<>"", -J44+K44*VLOOKUP(A44, BACKEND1!$A:$G,6,FALSE),0)))+ (C44+D44-E44)*VLOOKUP(A44, BACKEND1!$A:$G,5,FALSE)+G44 -> 0
A45: Burger Buns | B45: Pcs | F45: Pcs | L45: Pcs | M45: =IF(AND(H45<>"", J45<>""), H45-J45, IF(H45<>"", H45-I45*VLOOKUP(A45, BACKEND1!$A:$G,6,FALSE), IF(J45<>"", -J45+K45*VLOOKUP(A45, BACKEND1!$A:$G,6,FALSE),0)))+ (C45+D45-E45)*VLOOKUP(A45, BACKEND1!$A:$G,5,FALSE)+G45 -> 0
A46: Slider Buns | B46: Pcs | F46: Pcs | L46: Pcs | M46: =IF(AND(H46<>"", J46<>""), H46-J46, IF(H46<>"", H46-I46*VLOOKUP(A46, BACKEND1!$A:$G,6,FALSE), IF(J46<>"", -J46+K46*VLOOKUP(A46, BACKEND1!$A:$G,6,FALSE),0)))+ (C46+D46-E46)*VLOOKUP(A46, BACKEND1!$A:$G,5,FALSE)+G46 -> 0
A47: Soup Buns | B47: Pcs | F47: Pcs | L47: Pcs | M47: =IF(AND(H47<>"", J47<>""), H47-J47, IF(H47<>"", H47-I47*VLOOKUP(A47, BACKEND1!$A:$G,6,FALSE), IF(J47<>"", -J47+K47*VLOOKUP(A47, BACKEND1!$A:$G,6,FALSE),0)))+ (C47+D47-E47)*VLOOKUP(A47, BACKEND1!$A:$G,5,FALSE)+G47 -> 0
A48: Baguette Bread | B48: Pcs | F48: Pcs | L48: Pcs | M48: =IF(AND(H48<>"", J48<>""), H48-J48, IF(H48<>"", H48-I48*VLOOKUP(A48, BACKEND1!$A:$G,6,FALSE), IF(J48<>"", -J48+K48*VLOOKUP(A48, BACKEND1!$A:$G,6,FALSE),0)))+ (C48+D48-E48)*VLOOKUP(A48, BACKEND1!$A:$G,5,FALSE)+G48 -> 0
A49: Foccacia Bread | B49: Pcs | F49: Pcs | L49: Pcs | M49: =IF(AND(H49<>"", J49<>""), H49-J49, IF(H49<>"", H49-I49*VLOOKUP(A49, BACKEND1!$A:$G,6,FALSE), IF(J49<>"", -J49+K49*VLOOKUP(A49, BACKEND1!$A:$G,6,FALSE),0)))+ (C49+D49-E49)*VLOOKUP(A49, BACKEND1!$A:$G,5,FALSE)+G49 -> 0
A50: White vinegar | B50: Bottles | F50: Liters | L50: Liters | M50: =IF(AND(H50<>"", J50<>""), H50-J50, IF(H50<>"", H50-I50*VLOOKUP(A50, BACKEND1!$A:$G,6,FALSE), IF(J50<>"", -J50+K50*VLOOKUP(A50, BACKEND1!$A:$G,6,FALSE),0)))+ (C50+D50-E50)*VLOOKUP(A50, BACKEND1!$A:$G,5,FALSE)+G50 -> 0
A51: Heinz ketchup bottles | B51: Bottles | F51: Bottles | L51: Bottles | M51: =IF(AND(H51<>"", J51<>""), H51-J51, IF(H51<>"", H51-I51*VLOOKUP(A51, BACKEND1!$A:$G,6,FALSE), IF(J51<>"", -J51+K51*VLOOKUP(A51, BACKEND1!$A:$G,6,FALSE),0)))+ (C51+D51-E51)*VLOOKUP(A51, BACKEND1!$A:$G,5,FALSE)+G51 -> 0
A52: Apple cider vinegar | B52: Pcs | F52: kg | L52: kg | M52: =IF(AND(H52<>"", J52<>""), H52-J52, IF(H52<>"", H52-I52*VLOOKUP(A52, BACKEND1!$A:$G,6,FALSE), IF(J52<>"", -J52+K52*VLOOKUP(A52, BACKEND1!$A:$G,6,FALSE),0)))+ (C52+D52-E52)*VLOOKUP(A52, BACKEND1!$A:$G,5,FALSE)+G52 -> 0
A53: Balsamic Vinegar | B53: Bottles | F53: Kg | L53: Kg | M53: =IF(AND(H53<>"", J53<>""), H53-J53, IF(H53<>"", H53-I53*VLOOKUP(A53, BACKEND1!$A:$G,6,FALSE), IF(J53<>"", -J53+K53*VLOOKUP(A53, BACKEND1!$A:$G,6,FALSE),0)))+ (C53+D53-E53)*VLOOKUP(A53, BACKEND1!$A:$G,5,FALSE)+G53 -> 0
A54: Tomato paste | B54: Tins | F54: Kg | L54: Kg | M54: =IF(AND(H54<>"", J54<>""), H54-J54, IF(H54<>"", H54-I54*VLOOKUP(A54, BACKEND1!$A:$G,6,FALSE), IF(J54<>"", -J54+K54*VLOOKUP(A54, BACKEND1!$A:$G,6,FALSE),0)))+ (C54+D54-E54)*VLOOKUP(A54, BACKEND1!$A:$G,5,FALSE)+G54 -> 0
A55: Tabasco | B55: Pcs | F55: Kgs | L55: Kgs | M55: =IF(AND(H55<>"", J55<>""), H55-J55, IF(H55<>"", H55-I55*VLOOKUP(A55, BACKEND1!$A:$G,6,FALSE), IF(J55<>"", -J55+K55*VLOOKUP(A55, BACKEND1!$A:$G,6,FALSE),0)))+ (C55+D55-E55)*VLOOKUP(A55, BACKEND1!$A:$G,5,FALSE)+G55 -> 0
... A64: Ketchup 5L | B64: Jerrycan | F64: kg | L64: kg | M64: =IF(AND(H64<>"", J64<>""), H64-J64, IF(H64<>"", H64-I64*VLOOKUP(A64, BACKEND1!$A:$G,6,FALSE), IF(J64<>"", -J64+K64*VLOOKUP(A64, BACKEND1!$A:$G,6,FALSE),0)))+ (C64+D64-E64)*VLOOKUP(A64, BACKEND1!$A:$G,5,FALSE)+G64 -> 0
A65: Dry Foods | M65: =IF(AND(H65<>"", J65<>""), H65-J65, IF(H65<>"", H65-I65*VLOOKUP(A65, BACKEND1!$A:$G,6,FALSE), IF(J65<>"", -J65+K65*VLOOKUP(A65, BACKEND1!$A:$G,6,FALSE),0)))+ (C65+D65-E65)*VLOOKUP(A65, BACKEND1!$A:$G,5,FALSE)+G65 -> 0
A66: Baking flour | B66: Pkts | F66: Kg | L66: Kg | M66: =IF(AND(H66<>"", J66<>""), H66-J66, IF(H66<>"", H66-I66*VLOOKUP(A66, BACKEND1!$A:$G,6,FALSE), IF(J66<>"", -J66+K66*VLOOKUP(A66, BACKEND1!$A:$G,6,FALSE),0)))+ (C66+D66-E66)*VLOOKUP(A66, BACKEND1!$A:$G,5,FALSE)+G66 -> 0
A67: Baking Powder | B67: Pkts | F67: Kg | L67: Kg | M67: =IF(AND(H67<>"", J67<>""), H67-J67, IF(H67<>"", H67-I67*VLOOKUP(A67, BACKEND1!$A:$G,6,FALSE), IF(J67<>"", -J67+K67*VLOOKUP(A67, BACKEND1!$A:$G,6,FALSE),0)))+ (C67+D67-E67)*VLOOKUP(A67, BACKEND1!$A:$G,5,FALSE)+G67 -> 0
A68: Basmati rice | B68: Kg | F68: Kg | L68: Kg | M68: =IF(AND(H68<>"", J68<>""), H68-J68, IF(H68<>"", H68-I68*VLOOKUP(A68, BACKEND1!$A:$G,6,FALSE), IF(J68<>"", -J68+K68*VLOOKUP(A68, BACKEND1!$A:$G,6,FALSE),0)))+ (C68+D68-E68)*VLOOKUP(A68, BACKEND1!$A:$G,5,FALSE)+G68 -> 0
A69: Corn flour | B69: Pkts | F69: Kg | L69: Kg | M69: =IF(AND(H69<>"", J69<>""), H69-J69, IF(H69<>"", H69-I69*VLOOKUP(A69, BACKEND1!$A:$G,6,FALSE), IF(J69<>"", -J69+K69*VLOOKUP(A69, BACKEND1!$A:$G,6,FALSE),0)))+ (C69+D69-E69)*VLOOKUP(A69, BACKEND1!$A:$G,5,FALSE)+G69 -> 0
A70: Oils, Fats & Creams | M70: =IF(AND(H70<>"", J70<>""), H70-J70, IF(H70<>"", H70-I70*VLOOKUP(A70, BACKEND1!$A:$G,6,FALSE), IF(J70<>"", -J70+K70*VLOOKUP(A70, BACKEND1!$A:$G,6,FALSE),0)))+ (C70+D70-E70)*VLOOKUP(A70, BACKEND1!$A:$G,5,FALSE)+G70 -> 0
A71: Cooking oil 20L | B71: Jerrycan | F71: Liters | L71: Liters | M71: =IF(AND(H71<>"", J71<>""), H71-J71, IF(H71<>"", H71-I71*VLOOKUP(A71, BACKEND1!$A:$G,6,FALSE), IF(J71<>"", -J71+K71*VLOOKUP(A71, BACKEND1!$A:$G,6,FALSE),0)))+ (C71+D71-E71)*VLOOKUP(A71, BACKEND1!$A:$G,5,FALSE)+G71 -> 0
A72: Croma Butter | B72: Kg | F72: Kg | L72: Kg | M72: =IF(AND(H72<>"", J72<>""), H72-J72, IF(H72<>"", H72-I72*VLOOKUP(A72, BACKEND1!$A:$G,6,FALSE), IF(J72<>"", -J72+K72*VLOOKUP(A72, BACKEND1!$A:$G,6,FALSE),0)))+ (C72+D72-E72)*VLOOKUP(A72, BACKEND1!$A:$G,5,FALSE)+G72 -> 0
A73: Prestige | B73: Kg | F73: Kg | L73: Kg | M73: =IF(AND(H73<>"", J73<>""), H73-J73, IF(H73<>"", H73-I73*VLOOKUP(A73, BACKEND1!$A:$G,6,FALSE), IF(J73<>"", -J73+K73*VLOOKUP(A73, BACKEND1!$A:$G,6,FALSE),0)))+ (C73+D73-E73)*VLOOKUP(A73, BACKEND1!$A:$G,5,FALSE)+G73 -> 0
...

Sheet 23rd-24thMAY
B2: WHOLE | F2: REMAINDER | L2: ACCOUNTABILITY
A3: Type | B3: U.O.M | C3: Opening | D3: Added | E3: Closing | F3: U.O.M | G3: Added | H3: Opening | I3: Units | J3: Closing | K3: Units | L3: U.O.M | M3: Used | N3: Transfer | O3: Damage
A4: Portioned Items: Meats & Others
A5: Carribean jerk | B5: Ptns | C5: ='22ndMAY'!E5 -> 38.02 | F5: Pcs | L5: Pcs | M5: =IF(AND(H5<>"", J5<>""), H5-J5, IF(H5<>"", H5-I5*VLOOKUP(A5, BACKEND2!$A:$G,6,FALSE), IF(J5<>"", -J5+K5*VLOOKUP(A5, BACKEND2!$A:$G,6,FALSE),0)))+ (C5+D5-E5)*VLOOKUP(A5, BACKEND2!$A:$G,5,FALSE)+G5 -> 114.06
A6: Chicken breast | B6: Ptns | C6: ='22ndMAY'!E6 -> 6 | F6: Pcs | L6: Pcs | M6: =IF(AND(H6<>"", J6<>""), H6-J6, IF(H6<>"", H6-I6*VLOOKUP(A6, BACKEND2!$A:$G,6,FALSE), IF(J6<>"", -J6+K6*VLOOKUP(A6, BACKEND2!$A:$G,6,FALSE),0)))+ (C6+D6-E6)*VLOOKUP(A6, BACKEND2!$A:$G,5,FALSE)+G6 -> 12
A7: Chicken wings | B7: Ptns | C7: ='22ndMAY'!E7 -> 6 | F7: Pcs | L7: Pcs | M7: =IF(AND(H7<>"", J7<>""), H7-J7, IF(H7<>"", H7-I7*VLOOKUP(A7, BACKEND2!$A:$G,6,FALSE), IF(J7<>"", -J7+K7*VLOOKUP(A7, BACKEND2!$A:$G,6,FALSE),0)))+ (C7+D7-E7)*VLOOKUP(A7, BACKEND2!$A:$G,5,FALSE)+G7 -> 30
A8: Chicken burger | B8: Ptns | C8: ='22ndMAY'!E8 -> 18 | F8: Ptns | L8: Ptns | M8: =IF(AND(H8<>"", J8<>""), H8-J8, IF(H8<>"", H8-I8*VLOOKUP(A8, BACKEND2!$A:$G,6,FALSE), IF(J8<>"", -J8+K8*VLOOKUP(A8, BACKEND2!$A:$G,6,FALSE),0)))+ (C8+D8-E8)*VLOOKUP(A8, BACKEND2!$A:$G,5,FALSE)+G8 -> 18
A9: Min Chicken burger | B9: Ptns | C9: ='22ndMAY'!E9 | F9: Pcs | L9: Pcs | M9: =IF(AND(H9<>"", J9<>""), H9-J9, IF(H9<>"", H9-I9*VLOOKUP(A9, BACKEND2!$A:$G,6,FALSE), IF(J9<>"", -J9+K9*VLOOKUP(A9, BACKEND2!$A:$G,6,FALSE),0)))+ (C9+D9-E9)*VLOOKUP(A9, BACKEND2!$A:$G,5,FALSE)+G9 -> 0
A10: Chicken lollipos | B10: Ptns | C10: ='22ndMAY'!E10 -> 3 | F10: Pcs | L10: Pcs | M10: =IF(AND(H10<>"", J10<>""), H10-J10, IF(H10<>"", H10-I10*VLOOKUP(A10, BACKEND2!$A:$G,6,FALSE), IF(J10<>"", -J10+K10*VLOOKUP(A10, BACKEND2!$A:$G,6,FALSE),0)))+ (C10+D10-E10)*VLOOKUP(A10, BACKEND2!$A:$G,5,FALSE)+G10 -> 24
A11: Chicken pizza | B11: Ptns | C11: ='22ndMAY'!E11 -> 13 | F11: Ptns | L11: Ptns | M11: =IF(AND(H11<>"", J11<>""), H11-J11, IF(H11<>"", H11-I11*VLOOKUP(A11, BACKEND2!$A:$G,6,FALSE), IF(J11<>"", -J11+K11*VLOOKUP(A11, BACKEND2!$A:$G,6,FALSE),0)))+ (C11+D11-E11)*VLOOKUP(A11, BACKEND2!$A:$G,5,FALSE)+G11 -> 13
A12: Chicken Tenders | B12: Ptns | C12: ='22ndMAY'!E12 | F12: Ptns | L12: Ptns | M12: =IF(AND(H12<>"", J12<>""), H12-J12, IF(H12<>"", H12-I12*VLOOKUP(A12, BACKEND2!$A:$G,6,FALSE), IF(J12<>"", -J12+K12*VLOOKUP(A12, BACKEND2!$A:$G,6,FALSE),0)))+ (C12+D12-E12)*VLOOKUP(A12, BACKEND2!$A:$G,5,FALSE)+G12 -> 0
A13: Chicken skewers | B13: Ptns | C13: ='22ndMAY'!E13 -> 8.5 | F13: Pcs | L13: Pcs | M13: =IF(AND(H13<>"", J13<>""), H13-J13, IF(H13<>"", H13-I13*VLOOKUP(A13, BACKEND2!$A:$G,6,FALSE), IF(J13<>"", -J13+K13*VLOOKUP(A13, BACKEND2!$A:$G,6,FALSE),0)))+ (C13+D13-E13)*VLOOKUP(A13, BACKEND2!$A:$G,5,FALSE)+G13 -> 76.5
